Workbook

Sheet OOMRSC-05
A1: OOMRSC-05
A2: Rev. 37 | C2: Cuadro de Control de Desempeño de Procesos
A3: Última Revisión: Abril 2026
R4: Mes/año: | S4: Julio 2026
A5: No. | B5: Proceso: | C5: Dirección: | D5: Área: | E5: # | F5: Indicador o Índice: | G5: Periodicidad | H5: Unidad de Medida | I5: Meta Anual | J5: Meta | K5: Meta | L5: Meta | M5: Meta | N5: Impacto | P5: Cumple: Sí/No | Q5: Cumplimiento | R5: Observación: | S5: Acción: | V5: Responsable: | AD5: META 1ER TRIM | AE5: 1ER PEM | AJ5: META ACUM 2DO TRIM | AK5: 2DO PEM | AL5: 2DO PEM ACUM | AQ5: META ACUM 3ER TRIM | AR5: 3ER PEM | AS5: 3ER PEM ACUM | AX5: META ACUM 4TO TRIM | AY5: 4TO PEM | AZ5: 4TO PEM ACUM
J6: 1er Trim. | K6: 2do Trim. | L6: 3er Trim. | M6: 4to Trim. | N6: Bajo | O6: Alto | S6: c | T6: ac | U6: snc | Z6: Enero | AA6: Febrero | AB6: Marzo | AC6: 1er Trimestre | AF6: Abril | AG6: Mayo | AH6: Junio | AI6: 2do Trimestre | AM6: Julio | AN6: Agosto | AO6: Septiembre | AP6: 3er Trimestre | AT6: Octubre | AU6: Noviembre | AV6: Diciembre | AW6: 4TO Trimestre
A7: 1 | B7: Responsabilidad de la Dirección | C7: General | D7: Sistema de Gestión de Calidad | E7: 0 | F7: Lograr el grado de eficacia del SGC determinado por auditorías e indicadores. | G7: Trimestral | H7: Porcentaje | I7: 85 | J7: 20 | K7: 20 | L7: 20 | M7: 25 | N7: n/a | P7: SI | Q7: 91 | R7: El grado de eficacia del SGC resultó en un 91% de cumplimiento. El resultado por indicadores fue del 90%, quedando en rango aceptable; y por auditorías fue de 92%, quedando en rango aceptable. | S7: NA | T7: NA | U7: NA | V7: Mariana Pérez | Z7: 92 | AA7: 91 | AB7: 90 | AC7: =AVERAGE(Z7:AB7) -> 91 | AD7: =J7 -> 20 | AE7: =(J7*AC7)/I7 -> 21.411765 | AF7: 90 | AG7: 90 | AH7: 91 | AI7: =AVERAGE(AF7:AH7) -> 90.333333 | AJ7: =J7+K7 -> 40 | AK7: =(K7*AI7)/I7 -> 21.254902 | AL7: =AE7+AK7 -> 42.666667 | AM7: =Q7 -> 91 | AP7: =AVERAGE(AM7:AO7) -> 91 | AQ7: =J7+K7+L7 -> 60 | AR7: =(L7*AP7)/I7 -> 21.411765 | AS7: =AE7+AK7+AR7 -> 64.078431 | AW7: =AVERAGE(AT7:AV7) -> #DIV/0! | AX7: =J7+K7+L7+M7 -> 85 | AY7: =(M7*AW7)/I7 -> #DIV/0! | AZ7: =AE7+AK7+AR7+AY7 -> #DIV/0!
D8: Dirección General | E8: 1 | F8: Cumplir con las metas establecidas por las direcciones adscritas a la Dirección General | G8: Trimestral | H8: Porcentaje | I8: 85 | J8: 20 | K8: 20 | L8: 20 | M8: 25 | N8: X | P8: SI | Q8: 0 | R8: Se cumplió con las metas de las direcciones adscritas a la Dirección General. | S8: NA | T8: NA | U8: NA | V8: Mariana Pérez | Z8: 0 | AA8: 0 | AB8: 88 | AC8: =SUM(Z8:AB8) -> 88 | AD8: =J8 -> 20 | AE8: =(J8*AC8)/I8 -> 20.705882 | AF8: 0 | AG8: 0 | AH8: 85 | AI8: =SUM(AF8:AH8) -> 85 | AJ8: =J8+K8 -> 40 | AK8: =(K8*AI8)/I8 -> 20 | AL8: =AE8+AK8 -> 40.705882 | AM8: =Q8 -> 0 | AP8: =SUM(AM8:AO8) -> 0 | AQ8: =J8+K8+L8 -> 60 | AR8: =(L8*AP8)/I8 -> 0 | AS8: =AE8+AK8+AR8 -> 40.705882 | AW8: =SUM(AT8:AV8) -> 0 | AX8: =J8+K8+L8+M8 -> 85 | AY8: =(M8*AW8)/I8 -> 0 | AZ8: =AE8+AK8+AR8+AY8 -> 40.705882
E9: 2 | F9: Mantener una relación de comunicación con el Consejo Consultivo. | G9: Trimestral | H9: Actas | I9: 11 | J9: 3 | K9: 3 | L9: 2 | M9: 3 | N9: X | P9: SI | Q9: 0 | R9: Se cumplió con 3 reuniones con el Consejo Consultivo. | S9: NA | T9: NA | U9: NA | V9: Mariana Pérez | Z9: 0 | AA9: 0 | AB9: 3 | AC9: =SUM(Z9:AB9) -> 3 | AD9: =J9 -> 3 | AE9: =AC9 -> 3 | AF9: 0 | AG9: 0 | AH9: 3 | AI9: =SUM(AF9:AH9) -> 3 | AJ9: =J9+K9 -> 6 | AK9: =AI9 -> 3 | AL9: =AE9+AK9 -> 6 | AM9: =Q9 -> 0 | AP9: =SUM(AM9:AO9) -> 0 | AQ9: =J9+K9+L9 -> 8 | AR9: =AP9 -> 0 | AS9: =AE9+AK9+AR9 -> 6 | AW9: =SUM(AT9:AV9) -> 0 | AX9: =J9+K9+L9+M9 -> 11 | AY9: =AW9 -> 0 | AZ9: =AE9+AK9+AR9+AY9 -> 6
A10: 2 | B10: Gestión de Recursos | C10: Administrativa | D10: Recursos Humanos | E10: 3 | F10: Remuneración del personal. | G10: Trimestral | H10: Cantidad | I10: 28 | J10: 6 | K10: 6 | L10: 8 | M10: 8 | N10: X | P10: SI | Q10: 0 | R10: Se cumplió con la remuneración del personal. | S10: NA | T10: NA | U10: NA | V10: Vicente Castro | Z10: 0 | AA10: 0 | AB10: 6 | AC10: =SUM(Z10:AB10) -> 6 | AD10: =J10 -> 6 | AE10: =AC10 -> 6 | AF10: 0 | AG10: 0 | AH10: 6 | AI10: =SUM(AF10:AH10) -> 6 | AJ10: =J10+K10 -> 12 | AK10: =AI10 -> 6 | AL10: =AE10+AK10 -> 12 | AM10: =Q10 -> 0 | AP10: =SUM(AM10:AO10) -> 0 | AQ10: =J10+K10+L10 -> 20 | AR10: =AP10 -> 0 | AS10: =AE10+AK10+AR10 -> 12 | AW10: =SUM(AT10:AV10) -> 0 | AX10: =J10+K10+L10+M10 -> 28 | AY10: =AW10 -> 0 | AZ10: =AE10+AK10+AR10+AY10 -> 12
E11: 4 | F11: Remuneración a jubilados y pensionados | G11: Trimestral | H11: Cantidad | I11: 28 | J11: 6 | K11: 6 | L11: 8 | M11: 8 | N11: X | P11: SI | Q11: 0 | R11: Se cumplió con la remuneración de jubilados y pensionados. | S11: NA | T11: NA | U11: NA | V11: Vicente Castro | Z11: 0 | AA11: 0 | AB11: 6 | AC11: =SUM(Z11:AB11) -> 6 | AD11: =J11 -> 6 | AE11: =AC11 -> 6 | AF11: 0 | AG11: 0 | AH11: 6 | AI11: =SUM(AF11:AH11) -> 6 | AJ11: =J11+K11 -> 12 | AK11: =AI11 -> 6 | AL11: =AE11+AK11 -> 12 | AM11: =Q11 -> 0 | AP11: =SUM(AM11:AO11) -> 0 | AQ11: =J11+K11+L11 -> 20 | AR11: =AP11 -> 0 | AS11: =AE11+AK11+AR11 -> 12 | AW11: =SUM(AT11:AV11) -> 0 | AX11: =J11+K11+L11+M11 -> 28 | AY11: =AW11 -> 0 | AZ11: =AE11+AK11+AR11+AY11 -> 12
E12: 5 | F12: Cumplir con el programa trimestral de capacitación. | G12: Trimestral | H12: Porcentaje | I12: 100 | J12: 25 | K12: 25 | L12: 25 | M12: 25 | N12: X | P12: SI | Q12: 0 | R12: Se cumplió con el programa tirmestral de capacitación. | S12: RC 04/2026 | T12: NA | U12: NA | V12: Ana Cecilia Ruiz | Z12: 0 | AA12: 0 | AB12: 86 | AC12: =SUM(Z12:AB12) -> 86 | AD12: =J12 -> 25 | AE12: =(J12*AC12)/I12 -> 21.5 | AF12: 0 | AG12: 0 | AH12: 100 | AI12: =SUM(AF12:AH12) -> 100 | AJ12: =J12+K12 -> 50 | AK12: =(K12*AI12)/I12 -> 25 | AL12: =AE12+AK12 -> 46.5 | AM12: =Q12 -> 0 | AP12: =SUM(AM12:AO12) -> 0 | AQ12: =J12+K12+L12 -> 75 | AR12: =(L12*AP12)/I12 -> 0 | AS12: =AE12+AK12+AR12 -> 46.5 | AW12: =SUM(AT12:AV12) -> 0 | AX12: =J12+K12+L12+M12 -> 100 | AY12: =(M12*AW12)/I12 -> 0 | AZ12: =AE12+AK12+AR12+AY12 -> 46.5
E13: 6 | F13: Evaluación del ambiente de trabajo. | G13: Anual | H13: Porcentaje | I13: 95 | J13: 0 | K13: 0 | L13: 0 | M13: 95 | N13: X | P13: SI | Q13: 0 | R13: El indicador es anual. | S13: NA | T13: NA | U13: NA | V13: Erika Acosta | Z13: 0 | AA13: 0 | AB13: 0 | AC13: =AVERAGE(Z13:AB13) -> 0 | AD13: =J13 -> 0 | AE13: =(J13*AC13)/I13 -> 0 | AF13: 0 | AG13: 0 | AH13: 0 | AI13: =AVERAGE(AF13:AH13) -> 0 | AJ13: =J13+K13 -> 0 | AK13: =(K13*AI13)/I13 -> 0 | AL13: =AE13+AK13 -> 0 | AM13: =Q13 -> 0 | AP13: =AVERAGE(AM13:AO13) -> 0 | AQ13: =J13+K13+L13 -> 0 | AR13: =(L13*AP13)/I13 -> 0 | AS13: =AE13+AK13+AR13 -> 0 | AW13: =AVERAGE(AT13:AV13) -> #DIV/0! | AX13: =J13+K13+L13+M13 -> 95 | AY13: =(M13*AW13)/I13 -> #DIV/0! | AZ13: =AE13+AK13+AR13+AY13 -> #DIV/0!
D14: Recursos Materiales | E14: 7 | F14: Evaluar el desempeño de proveedores de productos químicos críticos | G14: Mensual | H14: Porcentaje | I14: 100 | J14: 25 | K14: 25 | L14: 25 | M14: 25 | O14: X | P14: SI | Q14: 100 | R14: Se cumplió al 100% con la evaluación del desempeño de proveedores de productos químicos críticos. | S14: NA | T14: NA | U14: NA | V14: Xiomara López | Z14: 100 | AA14: 100 | AB14: 100 | AC14: =AVERAGE(Z14:AB14) -> 100 | AD14: =J14 -> 25 | AE14: =(J14*AC14)/I14 -> 25 | AF14: 100 | AG14: 100 | AH14: 100 | AI14: =AVERAGE(AF14:AH14) -> 100 | AJ14: =J14+K14 -> 50 | AK14: =(K14*AI14)/I14 -> 25 | AL14: =AE14+AK14 -> 50 | AM14: =Q14 -> 100 | AP14: =AVERAGE(AM14:AO14) -> 100 | AQ14: =J14+K14+L14 -> 75 | AR14: =(L14*AP14)/I14 -> 25 | AS14: =AE14+AK14+AR14 -> 75 | AW14: =AVERAGE(AT14:AV14) -> #DIV/0! | AX14: =J14+K14+L14+M14 -> 100 | AY14: =(M14*AW14)/I14 -> #DIV/0! | AZ14: =AE14+AK14+AR14+AY14 -> #DIV/0!
E15: 8 | F15: Atender las solicitudes de compra en el tiempo establecido. | G15: Mensual | H15: Porcentaje | I15: 100 | J15: 25 | K15: 25 | L15: 25 | M15: 25 | N15: X | P15: SI | Q15: 100 | R15: Se atendieron al 100% las solicitudes de compra en el tiempo establecido. | S15: NA | T15: NA | U15: NA | V15: Xiomara López | Z15: 100 | AA15: 100 | AB15: 100 | AC15: =AVERAGE(Z15:AB15) -> 100 | AD15: =J15 -> 25 | AE15: =(J15*AC15)/I15 -> 25 | AF15: 100 | AG15: 100 | AH15: 100 | AI15: =AVERAGE(AF15:AH15) -> 100 | AJ15: =J15+K15 -> 50 | AK15: =(K15*AI15)/I15 -> 25 | AL15: =AE15+AK15 -> 50 | AM15: =Q15 -> 100 | AP15: =AVERAGE(AM15:AO15) -> 100 | AQ15: =J15+K15+L15 -> 75 | AR15: =(L15*AP15)/I15 -> 25 | AS15: =AE15+AK15+AR15 -> 75 | AW15: =AVERAGE(AT15:AV15) -> #DIV/0! | AX15: =J15+K15+L15+M15 -> 100 | AY15: =(M15*AW15)/I15 -> #DIV/0! | AZ15: =AE15+AK15+AR15+AY15 -> #DIV/0!
E16: 9 | F16: Cumplir con el programa de verificación de activos fijos | G16: Mensual | H16: Porcentaje | I16: 100 | J16: 25 | K16: 25 | L16: 25 | M16: 25 | N16: X | P16: SI | Q16: 100 | R16: Se cumplió al 100% con el programa de verificación de activos fijos. | S16: NA | T16: NA | U16: NA | V16: Xiomara López | Z16: 100 | AA16: 100 | AB16: 100 | AC16: =AVERAGE(Z16:AB16) -> 100 | AD16: =J16 -> 25 | AE16: =(J16*AC16)/I16 -> 25 | AF16: 100 | AG16: 100 | AH16: 100 | AI16: =AVERAGE(AF16:AH16) -> 100 | AJ16: =J16+K16 -> 50 | AK16: =(K16*AI16)/I16 -> 25 | AL16: =AE16+AK16 -> 50 | AM16: =Q16 -> 100
D17: Contabilidad | E17: 10 | F17: Cumplir con el calendario contable y presupuestal. | G17: Mensual | H17: Documentos | I17: 29 | J17: 8 | K17: 7 | L17: 7 | M17: 7 | N17: X | P17: SI | Q17: 3 | R17: Se cumplió con el envío de los documentos del mes. | S17: NA | T17: NA | U17: NA | V17: María Fernanda Luzanilla | Z17: 3 | AA17: 2 | AB17: 3 | AC17: =SUM(Z17:AB17) -> 8 | AD17: =J17 -> 8 | AE17: =AC17 -> 8 | AF17: 3 | AG17: 2 | AH17: 2 | AI17: =SUM(AF17:AH17) -> 7 | AJ17: =J17+K17 -> 15 | AK17: =AI17 -> 7 | AL17: =AE17+AK17 -> 15 | AM17: =Q17 -> 3 | AP17: =SUM(AM17:AO17) -> 3 | AQ17: =J17+K17+L17 -> 22 | AR17: =AP17 -> 3 | AS17: =AE17+AK17+AR17 -> 18 | AW17: =SUM(AT17:AV17) -> 0 | AX17: =J17+K17+L17+M17 -> 29 | AY17: =AW17 -> 0 | AZ17: =AE17+AK17+AR17+AY17 -> 18
D18: Seguridad Industrial | E18: 11 | F18: Accidentes de trabajo | G18: Mensual | H18: Cantidad | I18: 0 | J18: 0 | K18: 0 | L18: 0 | M18: 0 | N18: n/a | P18: SI | Q18: 0 | R18: No hubo accidentes en el mes. | S18: NA | T18: NA | U18: NA | V18: Martín Ávila | Z18: 0 | AA18: 1 | AB18: 0 | AC18: =SUM(Z18:AB18) -> 1 | AD18: =J18 -> 0 | AE18: =AC18 -> 1 | AF18: 3 | AG18: 0 | AH18: 1 | AI18: =SUM(AF18:AH18) -> 4 | AJ18: =J18+K18 -> 0 | AK18: =AI18 -> 4 | AL18: =AE18+AK18 -> 5 | AM18: =Q18 -> 0 | AP18: =SUM(AM18:AO18) -> 0 | AQ18: =J18+K18+L18 -> 0 | AR18: =AP18 -> 0 | AS18: =AE18+AK18+AR18 -> 5 | AW18: =SUM(AT18:AV18) -> 0 | AX18: =J18+K18+L18+M18 -> 0 | AY18: =AW18 -> 0 | AZ18: =AE18+AK18+AR18+AY18 -> 5
D19: Licitaciones | E19: 12 | F19: Cumplir con el proceso de licitación pública o simplificada | G19: Mensual | H19: Porcentaje | I19: 100 | J19: 25 | K19: 25 | L19: 25 | M19: 25 | N19: X | P19: SI | Q19: 100 | R19: Se cumplió al 100% con el proceso de licitación pública o simplificada. | S19: NA | T19: NA | U19: NA | V19: Daniel Sandoval | Z19: 100 | AA19: 100 | AB19: 100 | AC19: =AVERAGE(Z19:AB19) -> 100 | AD19: =J19 -> 25 | AE19: =(J19*AC19)/I19 -> 25 | AF19: 100 | AG19: 100 | AH19: 100 | AI19: =AVERAGE(AF19:AH19) -> 100 | AJ19: =J19+K19 -> 50 | AK19: =(K19*AI19)/I19 -> 25 | AL19: =AE19+AK19 -> 50 | AM19: =Q19 -> 100 | AP19: =AVERAGE(AM19:AO19) -> 100 | AQ19: =J19+K19+L19 -> 75 | AR19: =(L19*AP19)/I19 -> 25 | AS19: =AE19+AK19+AR19 -> 75 | AW19: =AVERAGE(AT19:AV19) -> #DIV/0! | AX19: =J19+K19+L19+M19 -> 100 | AY19: =(M19*AW19)/I19 -> #DIV/0! | AZ19: =AE19+AK19+AR19+AY19 -> #DIV/0!
E20: 13 | F20: Cumplir con el proceso de adjudicación directa. | G20: Mensual | H20: Porcentaje | I20: 100 | J20: 25 | K20: 25 | L20: 25 | M20: 25 | N20: X | P20: SI | Q20: 100 | R20: Se cumplió al 100% con el proceso de adjudicación directa. | S20: NA | T20: NA | U20: NA | V20: Daniel Sandoval | Z20: 100 | AA20: 100 | AB20: 100 | AC20: =AVERAGE(Z20:AB20) -> 100 | AD20: =J20 -> 25 | AE20: =(J20*AC20)/I20 -> 25 | AF20: 100 | AG20: 100 | AH20: 100 | AI20: =AVERAGE(AF20:AH20) -> 100 | AJ20: =J20+K20 -> 50 | AK20: =(K20*AI20)/I20 -> 25 | AL20: =AE20+AK20 -> 50 | AM20: =Q20 -> 100 | AP20: =AVERAGE(AM20:AO20) -> 100 | AQ20: =J20+K20+L20 -> 75 | AR20: =(L20*AP20)/I20 -> 25 | AS20: =AE20+AK20+AR20 -> 75 | AW20: =AVERAGE(AT20:AV20) -> #DIV/0! | AX20: =J20+K20+L20+M20 -> 100 | AY20: =(M20*AW20)/I20 -> #DIV/0! | AZ20: =AE20+AK20+AR20+AY20 -> #DIV/0!
C21: Técnica | D21: Trámites Técnicos | E21: 14 | F21: Índice de programas federales gestionados | G21: Semestral | H21: Programa | I21: 1 | J21: 1 | K21: 0 | L21: 0 | M21: 0 | N21: X | P21: SI | Q21: 0 | R21: Durante el mes de marzo el organismo se adherió al programa federal PEAS. | S21: NA | T21: NA | U21: NA | V21: Lety Valle | Z21: 0 | AA21: 0 | AB21: 0 | AC21: =SUM(Z21:AB21) -> 0 | AD21: =J21 -> 1 | AE21: =AC21 -> 0 | AF21: 0 | AG21: 0 | AH21: 1 | AI21: =SUM(AF21:AH21) -> 1 | AJ21: =J21+K21 -> 1 | AK21: =AI21 -> 1 | AL21: =AE21+AK21 -> 1 | AM21: =Q21 -> 0 | AP21: =SUM(AM21:AO21) -> 0 | AQ21: =J21+K21+L21 -> 1 | AR21: =AP21 -> 0 | AS21: =AE21+AK21+AR21 -> 1 | AW21: =SUM(AT21:AV21) -> 0 | AX21: =J21+K21+L21+M21 -> 1 | AY21: =AW21 -> 0 | AZ21: =AE21+AK21+AR21+AY21 -> 1
A22: 3 | B22: Mantenimiento y Calibración | C22: Administrativa | D22: Informática | E22: 15 | F22: Cumplir con el programa de mantenimiento preventivo de los equipos de cómputo. | G22: Mensual | H22: Porcentaje | I22: 100 | J22: 25 | K22: 25 | L22: 25 | M22: 25 | N22: X | P22: SI | Q22: 100 | R22: Se cumplió al 100% con el programa de mantenimiento a los equipos de cómputo. | S22: NA | T22: NA | U22: NA | V22: Lizbeth Campa | Z22: 100 | AA22: 100 | AB22: 100 | AC22: =AVERAGE(Z22:AB22) -> 100 | AD22: =J22 -> 25 | AE22: =(J22*AC22)/I22 -> 25 | AF22: 100 | AG22: 100 | AH22: 100 | AI22: =AVERAGE(AF22:AH22) -> 100 | AJ22: =J22+K22 -> 50 | AK22: =(K22*AI22)/I22 -> 25 | AL22: =AE22+AK22 -> 50 | AM22: =Q22 -> 100 | AP22: =AVERAGE(AM22:AO22) -> 100 | AQ22: =J22+K22+L22 -> 75 | AR22: =(L22*AP22)/I22 -> 25 | AS22: =AE22+AK22+AR22 -> 75 | AW22: =AVERAGE(AT22:AV22) -> #DIV/0! | AX22: =J22+K22+L22+M22 -> 100 | AY22: =(M22*AW22)/I22 -> #DIV/0! | AZ22: =AE22+AK22+AR22+AY22 -> #DIV/0!
E23: 16 | F23: Solucionar las solicitudes de servicio. | G23: Mensual | H23: Porcentaje | I23: 95 | J23: 24 | K23: 24 | L23: 24 | M23: 23 | N23: X | P23: SI | Q23: 97 | R23: Se cumplió al 97% con la solución de las solicitudes de servicio. | S23: NA | T23: NA | U23: NA | V23: Lizbeth Campa | Z23: 96 | AA23: 100 | AB23: 96 | AC23: =AVERAGE(Z23:AB23) -> 97.333333 | AD23: =J23 -> 24 | AE23: =(J23*AC23)/I23 -> 24.589474 | AF23: 95 | AG23: 100 | AH23: 100 | AI23: =AVERAGE(AF23:AH23) -> 98.333333 | AJ23: =J23+K23 -> 48 | AK23: =(K23*AI23)/I23 -> 24.842105 | AL23: =AE23+AK23 -> 49.431579 | AM23: =Q23 -> 97 | AP23: =AVERAGE(AM23:AO23) -> 97 | AQ23: =J23+K23+L23 -> 72 | AR23: =(L23*AP23)/I23 -> 24.505263 | AS23: =AE23+AK23+AR23 -> 73.936842 | AW23: =AVERAGE(AT23:AV23) -> #DIV/0! | AX23: =J23+K23+L23+M23 -> 95 | AY23: =(M23*AW23)/I23 -> #DIV/0! | AZ23: =AE23+AK23+AR23+AY23 -> #DIV/0!
E24: 17 | F24: Asegurar la disponibilidad de los servicios críticos de informática. | G24: Mensual | H24: Porcentaje | I24: 95 | J24: 24 | K24: 24 | L24: 24 | M24: 23 | O24: X | P24: SI | Q24: 100 | R24: Se cumplió al 100% con la disponibilidad de los servicios críticos de informática. | S24: NA | T24: NA | U24: NA | V24: Lizbeth Campa | Z24: 100 | AA24: 100 | AB24: 100 | AC24: =AVERAGE(Z24:AB24) -> 100 | AD24: =J24 -> 24 | AE24: =(J24*AC24)/I24 -> 25.263158 | AF24: 100 | AG24: 100 | AH24: 100 | AI24: =AVERAGE(AF24:AH24) -> 100 | AJ24: =J24+K24 -> 48 | AK24: =(K24*AI24)/I24 -> 25.263158 | AL24: =AE24+AK24 -> 50.526316 | AM24: =Q24 -> 100 | AP24: =AVERAGE(AM24:AO24) -> 100 | AQ24: =J24+K24+L24 -> 72 | AR24: =(L24*AP24)/I24 -> 25.263158 | AS24: =AE24+AK24+AR24 -> 75.789474 | AW24: =AVERAGE(AT24:AV24) -> #DIV/0! | AX24: =J24+K24+L24+M24 -> 95 | AY24: =(M24*AW24)/I24 -> #DIV/0! | AZ24: =AE24+AK24+AR24+AY24 -> #DIV/0!
D25: Seguridad Industrial | E25: 18 | F25: Revisión de instalaciones | G25: Mensual | H25: Porcentaje | I25: 100 | J25: 25 | K25: 25 | L25: 25 | M25: 25 | N25: X | P25: SI | Q25: 100 | R25: Se cumplió al 100% con el programa de revisión de instalaciones. | S25: NA | T25: NA | U25: NA | V25: Martín Ávila | Z25: 100 | AA25: 100 | AB25: 100 | AC25: =AVERAGE(Z25:AB25) -> 100 | AD25: =J25 -> 25 | AE25: =(J25*AC25)/I25 -> 25 | AF25: 100 | AG25: 100 | AH25: 100 | AI25: =AVERAGE(AF25:AH25) -> 100 | AJ25: =J25+K25 -> 50 | AK25: =(K25*AI25)/I25 -> 25 | AL25: =AE25+AK25 -> 50 | AM25: =Q25 -> 100 | AP25: =AVERAGE(AM25:AO25) -> 100 | AQ25: =J25+K25+L25 -> 75 | AR25: =(L25*AP25)/I25 -> 25 | AS25: =AE25+AK25+AR25 -> 75 | AW25: =AVERAGE(AT25:AV25) -> #DIV/0! | AX25: =J25+K25+L25+M25 -> 100 | AY25: =(M25*AW25)/I25 -> #DIV/0! | AZ25: =AE25+AK25+AR25+AY25 -> #DIV/0!
D26: Mtto. y servicios generales | E26: 19 | F26: Cumplimiento al programa anual de mantenimiento preventivo a edificios. | G26: Mensual | H26: Cantidad | I26: 804 | J26: 202 | K26: 203 | L26: 202 | M26: 197 | N26: X | P26: NO | Q26: 30 | R26: Se cumplió con el programa anual de mantenimiento preventivo a edificios. | S26: RC 09/2026 | T26: NA | U26: NA | V26: Jazmín Sortillón | Z26: 65 | AA26: 65 | AB26: 72 | AC26: =SUM(Z26:AB26) -> 202 | AD26: =J26 -> 202 | AE26: =AC26 -> 202 | AF26: 66 | AG26: 63 | AH26: 74 | AI26: =SUM(AF26:AH26) -> 203 | AJ26: =J26+K26 -> 405 | AK26: =AI26 -> 203 | AL26: =AE26+AK26 -> 405 | AM26: =Q26 -> 30 | AP26: =SUM(AM26:AO26) -> 30 | AQ26: =J26+K26+L26 -> 607 | AR26: =AP26 -> 30 | AS26: =AE26+AK26+AR26 -> 435 | AW26: =SUM(AT26:AV26) -> 0 | AX26: =J26+K26+L26+M26 -> 804 | AY26: =AW26 -> 0 | AZ26: =AE26+AK26+AR26+AY26 -> 435
E27: 20 | F27: Cumplimiento al programa anual de mantenimiento preventivo para vehículos de transporte | G27: Mensual | H27: Porcentaje | I27: 95 | J27: 24 | K27: 24 | L27: 24 | M27: 23 | O27: X | P27: SI | Q27: 100 | R27: Se cumplió al 100% con el programa anual de mantenimiento preventivo para vehículos de transporte. | S27: NA | T27: NA | U27: NA | V27: Jazmín Sortillón | Z27: 100 | AA27: 100 | AB27: 100 | AC27: =AVERAGE(Z27:AB27) -> 100 | AD27: =J27 -> 24 | AE27: =(J27*AC27)/I27 -> 25.263158 | AF27: 100 | AG27: 100 | AH27: 100 | AI27: =AVERAGE(AF27:AH27) -> 100 | AJ27: =J27+K27 -> 48 | AK27: =(K27*AI27)/I27 -> 25.263158 | AL27: =AE27+AK27 -> 50.526316 | AM27: =Q27 -> 100 | AP27: =AVERAGE(AM27:AO27) -> 100 | AQ27: =J27+K27+L27 -> 72 | AR27: =(L27*AP27)/I27 -> 25.263158 | AS27: =AE27+AK27+AR27 -> 75.789474 | AW27: =AVERAGE(AT27:AV27) -> #DIV/0! | AX27: =J27+K27+L27+M27 -> 95 | AY27: =(M27*AW27)/I27 -> #DIV/0! | AZ27: =AE27+AK27+AR27+AY27 -> #DIV/0!
E28: 21 | F28: Cumplimiento al abastecimiento de las dotaciones de gasolina autorizadas. | G28: Mensual | H28: Reportes | I28: 59 | J28: 14 | K28: 15 | L28: 15 | M28: 15 | N28: X | P28: SI | Q28: 5 | R28: Se cumplió con el abastecimiento de las dotaciones de gasolina. | S28: NA | T28: NA | U28: NA | V28: Jazmín Sortillón | Z28: 5 | AA28: 4 | AB28: 5 | AC28: =SUM(Z28:AB28) -> 14 | AD28: =J28 -> 14 | AE28: =AC28 -> 14 | AF28: 5 | AG28: 5 | AH28: 5 | AI28: =SUM(AF28:AH28) -> 15 | AJ28: =J28+K28 -> 29 | AK28: =AI28 -> 15 | AL28: =AE28+AK28 -> 29 | AM28: =Q28 -> 5 | AP28: =SUM(AM28:AO28) -> 5 | AQ28: =J28+K28+L28 -> 44 | AR28: =AP28 -> 5 | AS28: =AE28+AK28+AR28 -> 34 | AW28: =SUM(AT28:AV28) -> 0 | AX28: =J28+K28+L28+M28 -> 59 | AY28: =AW28 -> 0 | AZ28: =AE28+AK28+AR28+AY28 -> 34
E29: 22 | F29: Cumplimiento a las solicitudes de mantenimiento correctivo para vehículos de transporte | G29: Trimestral | H29: Porcentaje | I29: 95 | J29: 24 | K29: 24 | L29: 24 | M29: 23 | O29: X | P29: SI | Q29: 100 | R29: Se cumplió al 100% con las solicitudes de mantenimiento correctivo para vehículos de transporte. | S29: NA | T29: NA | U29: NA | V29: Jazmín Sortillón | Z29: 100 | AA29: 100 | AB29: 100 | AC29: =AVERAGE(Z29:AB29) -> 100 | AD29: =J29 -> 24 | AE29: =(J29*AC29)/I29 -> 25.263158 | AF29: 100 | AG29: 100 | AH29: 100 | AI29: =AVERAGE(AF29:AH29) -> 100 | AJ29: =J29+K29 -> 48 | AK29: =(K29*AI29)/I29 -> 25.263158 | AL29: =AE29+AK29 -> 50.526316 | AM29: =Q29 -> 100 | AP29: =AVERAGE(AM29:AO29) -> 100 | AQ29: =J29+K29+L29 -> 72 | AR29: =(L29*AP29)/I29 -> 25.263158 | AS29: =AE29+AK29+AR29 -> 75.789474 | AW29: =AVERAGE(AT29:AV29) -> #DIV/0! | AX29: =J29+K29+L29+M29 -> 95 | AY29: =(M29*AW29)/I29 -> #DIV/0! | AZ29: =AE29+AK29+AR29+AY29 -> #DIV/0!
E30: 23 | F30: Cumplimiento al programa anual de intendencia | G30: Mensual | H30: Registros | I30: 1768 | J30: 442 | K30: 442 | L30: 442 | M30: 442 | N30: X | P30: SI | Q30: 136 | R30: Se cumplió con el programa anual de intendencia. | S30: NA | T30: NA | U30: NA | V30: Jazmín Sortillón | Y30: 170 | Z30: 136 | AA30: 136 | AB30: 170 | AC30: =SUM(Z30:AB30) -> 442 | AD30: =J30 -> 442 | AE30: =AC30 -> 442 | AF30: 136 | AG30: 136 | AH30: 170 | AI30: =SUM(AF30:AH30) -> 442 | AJ30: =J30+K30 -> 884 | AK30: =AI30 -> 442 | AL30: =AE30+AK30 -> 884 | AM30: =Q30 -> 136 | AP30: =SUM(AM30:AO30) -> 136 | AQ30: =J30+K30+L30 -> 1326 | AR30: =AP30 -> 136 | AS30: =AE30+AK30+AR30 -> 1020 | AW30: =SUM(AT30:AV30) -> 0 | AX30: =J30+K30+L30+M30 -> 1768 | AY30: =AW30 -> 0 | AZ30: =AE30+AK30+AR30+AY30 -> 1020
C31: Técnica | D31: Mantenimiento de Redes | E31: 24 | F31: Atender los reportes de los usuarios de la ciudad. | G31: Mensual | H31: Porcentaje | I31: 100 | J31: 25 | K31: 25 | L31: 25 | M31: 25 | O31: X | P31: SI | Q31: 103 | R31: Se cumplió con la atención de reportes de los usuarios. | S31: NA | T31: AC 14/2025 | U31: NA | V31: Denis Arias | W31: Vence 30 Diciembre 2025. Replanteo al 31 Diciembre 2026. | Z31: 108 | AA31: 109 | AB31: 143 | AC31: =AVERAGE(Z31:AB31) -> 120 | AD31: =J31 -> 25 | AE31: =(J31*AC31)/I31 -> 30 | AF31: 120 | AG31: 120 | AH31: 101 | AI31: =AVERAGE(AF31:AH31) -> 113.66667 | AJ31: =J31+K31 -> 50 | AK31: =(K31*AI31)/I31 -> 28.416667 | AL31: =AE31+AK31 -> 58.416667 | AM31: =Q31 -> 103 | AP31: =AVERAGE(AM31:AO31) -> 103 | AQ31: =J31+K31+L31 -> 75 | AR31: =(L31*AP31)/I31 -> 25.75 | AS31: =AE31+AK31+AR31 -> 84.166667 | AW31: =AVERAGE(AT31:AV31) -> #DIV/0! | AX31: =J31+K31+L31+M31 -> 100 | AY31: =(M31*AW31)/I31 -> #DIV/0! | AZ31: =AE31+AK31+AR31+AY31 -> #DIV/0!
D32: Control de Calidad | E32: 25 | F32: Cumplir con programa de calibración y verificación de equipos de medición. | G32: Trimestral | H32: Calibraciones y/o Verificaciones | I32: 157 | J32: 31 | K32: 43 | L32: 47 | M32: 36 | O32: X | P32: SI | Q32: 0 | R32: Se cumple con el programa de calibraciones de equipos de medición. | S32: NA | T32: NA | U32: NA | V32: Lenia Luzanilla | Z32: 0 | AA32: 0 | AB32: 28 | AC32: =SUM(Z32:AB32) -> 28 | AD32: =J32 -> 31 | AE32: =AC32 -> 28 | AF32: 0 | AG32: 0 | AH32: 45 | AI32: =SUM(AF32:AH32) -> 45 | AJ32: =J32+K32 -> 74 | AK32: =AI32 -> 45 | AL32: =AE32+AK32 -> 73 | AM32: =Q32 -> 0 | AP32: =SUM(AM32:AO32) -> 0 | AQ32: =J32+K32+L32 -> 121 | AR32: =AP32 -> 0 | AS32: =AE32+AK32+AR32 -> 73 | AW32: =SUM(AT32:AV32) -> 0 | AX32: =J32+K32+L32+M32 -> 157 | AY32: =AW32 -> 0 | AZ32: =AE32+AK32+AR32+AY32 -> 73
D33: Plantas Potabilizadoras | E33: 26 | F33: Índice de cumplimiento de los programas de mantenimiento a instalaciones y mantenimiento electromecánico preventivo y correctivo | G33: Mensual | H33: Porcentaje | I33: 100 | J33: 25 | K33: 25 | L33: 25 | M33: 25 | O33: X | P33: SI | Q33: 100 | R33: Se cumplió al 100% con los programas de mantenimiento a instalaciones y mantenimiento electromecánico preventivo y correctivo. | S33: NA | T33: AC 06/2026 | U33: NA | V33: Aracely Galvez | W33: Vence 31 Diciembre 2026. | Z33: 100 | AA33: 100 | AB33: 100 | AC33: =AVERAGE(Z33:AB33) -> 100 | AD33: =J33 -> 25 | AE33: =(J33*AC33)/I33 -> 25 | AF33: 100 | AG33: 100 | AH33: 100 | AI33: =AVERAGE(AF33:AH33) -> 100 | AJ33: =J33+K33 -> 50 | AK33: =(K33*AI33)/I33 -> 25 | AL33: =AE33+AK33 -> 50 | AM33: =Q33 -> 100 | AP33: =AVERAGE(AM33:AO33) -> 100 | AQ33: =J33+K33+L33 -> 75 | AR33: =(L33*AP33)/I33 -> 25 | AS33: =AE33+AK33+AR33 -> 75 | AW33: =AVERAGE(AT33:AV33) -> #DIV/0! | AX33: =J33+K33+L33+M33 -> 100 | AY33: =(M33*AW33)/I33 -> #DIV/0! | AZ33: =AE33+AK33+AR33+AY33 -> #DIV/0!
D34: Alcantarillado y Saneamiento | E34: 27 | F34: Programa de mantenimiento de redes sanitaria | G34: Mensual | H34: Porcentaje | I34: 100 | J34: 25 | K34: 25 | L34: 25 | M34: 25 | O34: X | P34: SI | Q34: 107 | R34: Se cumplió con el programa de mantenimiento de redes sanitaria. | S34: NA | T34: NA | U34: NA | V34: Jorge Fernández | Z34: 107 | AA34: 105 | AB34: 107 | AC34: =AVERAGE(Z34:AB34) -> 106.33333 | AD34: =J34 -> 25 | AE34: =(J34*AC34)/I34 -> 26.583333 | AF34: 110 | AG34: 105 | AH34: 107 | AI34: =AVERAGE(AF34:AH34) -> 107.33333 | AJ34: =J34+K34 -> 50 | AK34: =(K34*AI34)/I34 -> 26.833333 | AL34: =AE34+AK34 -> 53.416667 | AM34: =Q34 -> 107 | AP34: =AVERAGE(AM34:AO34) -> 107 | AQ34: =J34+K34+L34 -> 75 | AR34: =(L34*AP34)/I34 -> 26.75 | AS34: =AE34+AK34+AR34 -> 80.166667 | AW34: =AVERAGE(AT34:AV34) -> #DIV/0! | AX34: =J34+K34+L34+M34 -> 100 | AY34: =(M34*AW34)/I34 -> #DIV/0! | AZ34: =AE34+AK34+AR34+AY34 -> #DIV/0!
D35: Suburbano Técnico | E35: 28 | F35: Cumplir con el programa anual de mantenimiento preventivo a equipos de cloración y dosificación | G35: Semestral | H35: Porcentaje | I35: 100 | J35: 0 | K35: 50 | L35: 0 | M35: 50 | O35: X | P35: SI | Q35: 0 | R35: Se cumplió al 100% con el programa de mantenimiento preventivo a equipos de cloración y dosificación del semestre. | S35: NA | T35: NA | U35: NA | V35: Mario Mendoza | Z35: 0 | AA35: 0 | AB35: 0 | AC35: =AVERAGE(Z35:AB35) -> 0 | AD35: =J35 -> 0 | AE35: =(J35*AC35)/I35 -> 0 | AF35: 0 | AG35: 0 | AH35: 100 | AI35: =AH35 -> 100 | AJ35: =J35+K35 -> 50 | AK35: =(K35*AI35)/I35 -> 50 | AL35: =AE35+AK35 -> 50 | AM35: =Q35 -> 0 | AP35: =AVERAGE(AM35:AO35) -> 0 | AQ35: =J35+K35+L35 -> 50 | AR35: =(L35*AP35)/I35 -> 0 | AS35: =AE35+AK35+AR35 -> 50 | AW35: =AV35 -> 0 | AX35: =J35+K35+L35+M35 -> 100 | AY35: =(M35*AW35)/I35 -> 0 | AZ35: =AE35+AK35+AR35+AY35 -> 50
E36: 29 | F36: Cumplir con el programa anual de mantenimiento preventivo y toma de parámetros eléctricos y mecánicos | G36: Mensual | H36: Porcentaje | I36: 100 | J36: 25 | K36: 25 | L36: 25 | M36: 25 | O36: X | P36: SI | Q36: 100 | R36: Se cumplió al 100% con el programa de mantenimiento preventivo. | S36: NA | T36: NA | U36: NA | V36: Mario Mendoza | Z36: 100 | AA36: 100 | AB36: 100 | AC36: =AVERAGE(Z36:AB36) -> 100 | AD36: =J36 -> 25 | AE36: =(J36*AC36)/I36 -> 25 | AF36: 100 | AG36: 100 | AH36: 100 | AI36: =AVERAGE(AF36:AH36) -> 100 | AJ36: =J36+K36 -> 50 | AK36: =(K36*AI36)/I36 -> 25 | AL36: =AE36+AK36 -> 50 | AM36: =Q36 -> 100 | AP36: =AVERAGE(AM36:AO36) -> 100 | AQ36: =J36+K36+L36 -> 75 | AR36: =(L36*AP36)/I36 -> 25 | AS36: =AE36+AK36+AR36 -> 75 | AW36: =AVERAGE(AT36:AV36) -> #DIV/0! | AX36: =J36+K36+L36+M36 -> 100 | AY36: =(M36*AW36)/I36 -> #DIV/0! | AZ36: =AE36+AK36+AR36+AY36 -> #DIV/0!
A37: 4 | B37: Comercialización | C37: Comercial | D37: Padrón de Usuarios | E37: 30 | F37: Cumplir con el programa de mantenimiento anual de padrón de usuarios. | G37: Mensual | H37: Visitas | I37: 250000 | J37: 62500 | K37: 62500 | L37: 62500 | M37: 62500 | N37: X | P37: SI | Q37: 29892 | R37: Se cumplió con el programa anual de padrón de usuarios. | S37: NA | T37: NA | U37: NA | V37: Ana Lilián Núñez | Z37: 22496 | AA37: 23800 | AB37: 29089 | AC37: =SUM(Z37:AB37) -> 75385 | AD37: =J37 -> 62500 | AE37: =AC37 -> 75385 | AF37: 26161 | AG37: 24760 | AH37: 22733 | AI37: =SUM(AF37:AH37) -> 73654 | AJ37: =J37+K37 -> 125000 | AK37: =AI37 -> 73654 | AL37: =AE37+AK37 -> 149039 | AM37: =Q37 -> 29892 | AP37: =SUM(AM37:AO37) -> 29892 | AQ37: =J37+K37+L37 -> 187500 | AR37: =AP37 -> 29892 | AS37: =AE37+AK37+AR37 -> 178931 | AW37: =SUM(AT37:AV37) -> 0 | AX37: =J37+K37+L37+M37 -> 250000 | AY37: =AW37 -> 0 | AZ37: =AE37+AK37+AR37+AY37 -> 178931
E38: 31 | F38: Cobertura de Agua Potable | G38: Trimestral | H38: Porcentaje | I38: 95 | J38: 24 | K38: 24 | L38: 24 | M38: 23 | N38: X | P38: SI | Q38: 0 | R38: Se cumplió con la cobertura de agua potable. | S38: NA | T38: NA | U38: NA | V38: Ana Lilián Núñez | Z38: 0 | AA38: 0 | AB38: 98.34 | AC38: =SUM(Z38:AB38) -> 98.34 | AD38: =J38 -> 24 | AE38: =(J38*AC38)/I38 -> 24.843789 | AF38: 0 | AG38: 0 | AH38: 96.62 | AI38: =SUM(AF38:AH38) -> 96.62 | AJ38: =J38+K38 -> 48 | AK38: =(K38*AI38)/I38 -> 24.409263 | AL38: =AE38+AK38 -> 49.253053 | AM38: =Q38 -> 0 | AP38: =SUM(AM38:AO38) -> 0 | AQ38: =J38+K38+L38 -> 72 | AR38: =(L38*AP38)/I38 -> 0 | AS38: =AE38+AK38+AR38 -> 49.253053 | AW38: =SUM(AT38:AV38) -> 0 | AX38: =J38+K38+L38+M38 -> 95 | AY38: =(M38*AW38)/I38 -> 0 | AZ38: =AE38+AK38+AR38+AY38 -> 49.253053
D39: Control y Servicios | E39: 32 | F39: Recaudación por visitas efectivas. | G39: Mensual | H39: Pesos | I39: 100000000 | J39: 25000000 | K39: 25000000 | L39: 25000000 | M39: 25000000 | O39: X | P39: SI | Q39: 17355517 | R39: Se logró superar la meta de recaudación por visitas efectivas. | S39: NA | T39: NA | U39: NA | V39: Irasema Moreno | Z39: 17624327 | AA39: 15259649 | AB39: 17252966 | AC39: =SUM(Z39:AB39) -> 50136942 | AD39: =J39 -> 25000000 | AE39: =AC39 -> 50136942 | AF39: 15378065 | AG39: 17262698 | AH39: 16074509 | AI39: =SUM(AF39:AH39) -> 48715271 | AJ39: =J39+K39 -> 50000000 | AK39: =AI39 -> 48715271 | AL39: =AE39+AK39 -> 98852213 | AM39: =Q39 -> 17355517 | AP39: =SUM(AM39:AO39) -> 17355517 | AQ39: =J39+K39+L39 -> 75000000 | AR39: =AP39 -> 17355517 | AS39: =AE39+AK39+AR39 -> 1.1620773e+08 | AW39: =SUM(AT39:AV39) -> 0 | AX39: =J39+K39+L39+M39 -> 100000000 | AY39: =AW39 -> 0 | AZ39: =AE39+AK39+AR39+AY39 -> 1.1620773e+08
E40: 33 | F40: Recaudación por cobranza especial. | G40: Mensual | H40: Pesos | I40: 80000000 | J40: 20000000 | K40: 20000000 | L40: 20000000 | M40: 20000000 | O40: X | P40: SI | Q40: 11539795 | R40: Se logró superar la meta de recaudación por cobranza especial. | S40: NA | T40: NA | U40: NA | V40: Irasema Moreno | Z40: 10383362 | AA40: 8990596.7 | AB40: 12356619 | AC40: =SUM(Z40:AB40) -> 31730578 | AD40: =J40 -> 20000000 | AE40: =AC40 -> 31730578 | AF40: 10308285 | AG40: 10347694 | AH40: 11095969 | AI40: =SUM(AF40:AH40) -> 31751948 | AJ40: =J40+K40 -> 40000000 | AK40: =AI40 -> 31751948 | AL40: =AE40+AK40 -> 63482526 | AM40: =Q40 -> 11539795 | AP40: =SUM(AM40:AO40) -> 11539795 | AQ40: =J40+K40+L40 -> 60000000 | AR40: =AP40 -> 11539795 | AS40: =AE40+AK40+AR40 -> 75022320 | AW40: =SUM(AT40:AV40) -> 0 | AX40: =J40+K40+L40+M40 -> 80000000 | AY40: =AW40 -> 0 | AZ40: =AE40+AK40+AR40+AY40 -> 75022320
...

Sheet REPORTES DE CORRECCIÓN
B3: 2023 | C3: RC 4/2023 | D3: OCI | E3: CERRADA
C4: RC 8, 9/2023 | D4: SGC | E4: CERRADA
B5: 2024 | C5: RC 01 | D5: MIGUEL | E5: CERRADA
C6: RC 02 | D6: HECTOR | E6: CERRADA
C7: RC 03 | D7: MIGUEL | E7: CERRADA
C8: RC 04 | D8: HECTOR | E8: CERRADA
C9: RC 05 | D9: HECTOR | E9: CERRADA
C10: RC 06 | D10: PADRÓN | E10: CERRADA
C11: RC 07 | D11: HECTOR | E11: CERRADA
C12: RC 08 | D12: HECTOR | E12: CERRADA
C13: RC 09 | D13: EVELYN | E13: CERRADA
B14: 2025 | C14: RC 01 | D14: EVELYN | E14: CERRADA
C15: RC 02 | D15: PADRÓN | E15: CERRADA
C16: RC 03 | D16: PADRÓN | E16: CERRADA
C17: RC 04 | D17: MIGUEL | E17: CERRADA
C18: RC 05 | D18: ALFREDO | E18: CERRADA
C19: RC 06 | D19: MIGUEL | E19: CERRADA
C20: RC 07 | D20: EVELYN | E20: CERRADA
C21: RC 08 | D21: HECTOR | E21: ABIERTA
C22: RC 09 | D22: EVELYN | E22: CERRADA
C23: RC 10 | D23: MIGUEL | E23: CERRADA
C24: RC 11 | D24: Ana Cecilia | E24: CERRADA
C25: RC 12 | D25: EVELYN | E25: ABIERTA
B26: 2026 | C26: RC 01 | D26: MIGUEL | E26: CERRADA
C27: RC 02 | D27: EVELYN | E27: CERRADA
C28: RC 03 | D28: EVELYN | E28: ABIERTA
C29: RC 04 | D29: ANA CECILIA | E29: ABIERTA
C30: RC 05 | D30: MIGUEL | E30: CERRADA
C31: RC 06 | D31: Jazmín Sortillón | E31: CERRADA
C32: RC 07 | D32: EVELYN | E32: ABIERTA
C33: RC 08 | D33: MIGUEL | E33: ABIERTA
C34: RC 09 | D34: JAZMÍN | E34: ABIERTA

Sheet Hoja1
C5: Técnica | D5: Trámites Técnicos | E5: Índice de programas federales gestionados | F5: ='OOMRSC-05'!P21 -> SI | G5: ='OOMRSC-05'!Q21 -> 0
C6: Técnica | D6: Supervisión de Obras | E6: Cumplir con tiempo, costo y calidad definidos en la supervisión de obras. | F6: ='OOMRSC-05'!P94 -> SI | G6: ='OOMRSC-05'!Q94 -> 100
D7: Proyectos e Infraestructura | E7: Elaboración de prefactibilidades | F7: ='OOMRSC-05'!P95 -> SI | G7: ='OOMRSC-05'!Q95 -> 100
E8: Aprobación de proyectos de agua potable y/o alcantarillado sanitario | F8: ='OOMRSC-05'!P96 -> SI | G8: ='OOMRSC-05'!Q96 -> 100
E9: Elaboración de proyectos de agua potable y/o alcantarillado sanitario | F9: ='OOMRSC-05'!P97 -> SI | G9: ='OOMRSC-05'!Q97 -> 100
E10: Elaboración de viabilidad comercial e industrial | F10: ='OOMRSC-05'!P98 -> SI | G10: ='OOMRSC-05'!Q98 -> 100
D11: Sectorización Hidrométrica e Innovación | E11: Elaboración de proyectos para el mejoramiento de la eficiencia física y/o energética | F11: ='OOMRSC-05'!P99 -> SI | G11: ='OOMRSC-05'!Q99 -> 100
E12: Detecciones de infraestructura subterránea. | F12: ='OOMRSC-05'!P100 -> SI | G12: ='OOMRSC-05'!Q100 -> 100
D13: Trámites Técnicos | E13: Índice de cumplimiento de tiempo para cálculo de Derechos de Conexión. | F13: ='OOMRSC-05'!P101 -> SI | G13: ='OOMRSC-05'!Q101 -> 100
F14: =COUNTIF(F5:F13,"si") -> 9 | G14: =F14/9 -> 1
C16: Técnica | D16: Mantenimiento de Redes | E16: Atender los reportes de los usuarios de la ciudad. | F16: ='OOMRSC-05'!P31 -> SI | G16: ='OOMRSC-05'!Q31 -> 103
D17: Control de Calidad | E17: Cumplir con programa de calibración y verificación de equipos de medición. | F17: ='OOMRSC-05'!P32 -> SI | G17: ='OOMRSC-05'!Q32 -> 0
D18: Plantas Potabilizadoras | E18: Índice de cumplimiento de los programas de mantenimiento a instalaciones y mantenimiento electromecánico preventivo y correctivo | F18: ='OOMRSC-05'!P33 -> SI | G18: ='OOMRSC-05'!Q33 -> 100
D19: Alcantarillado y Saneamiento | E19: Programa de mantenimiento de redes sanitaria | F19: ='OOMRSC-05'!P34 -> SI | G19: ='OOMRSC-05'!Q34 -> 107
D20: Suburbano Técnico | E20: Cumplir con el programa anual de mantenimiento preventivo a equipos de cloración y dosificación | F20: ='OOMRSC-05'!P35 -> SI | G20: ='OOMRSC-05'!Q35 -> 0
E21: Cumplir con el programa anual de mantenimiento preventivo y toma de parámetros eléctrico y mecánicos | F21: ='OOMRSC-05'!P36 -> SI | G21: ='OOMRSC-05'!Q36 -> 100
C22: Técnica | D22: Control de Calidad | E22: Cumplimiento a NOM-127-SSA1-2021 aplicable a control de calidad. | F22: ='OOMRSC-05'!P52 -> SI | G22: ='OOMRSC-05'!Q52 -> 875
E23: Índice de cumplimiento en muestreos y análisis de agua potable. | F23: ='OOMRSC-05'!P53 -> SI | G23: ='OOMRSC-05'!Q53 -> 0
D24: Plantas Potabilizadoras | E24: Producción de agua en plantas potabilizadoras y pozos de área urbana | F24: ='OOMRSC-05'!P54 -> SI | G24: ='OOMRSC-05'!Q54 -> 3797664
E25: Índice de cobertura de macromedición | F25: ='OOMRSC-05'!P55 -> NO | G25: ='OOMRSC-05'!Q55 -> 57
D26: Alcantarillado y Saneamiento | E26: Índice de agua residual tratada. | F26: ='OOMRSC-05'!P56 -> SI | G26: ='OOMRSC-05'!Q56 -> 100
E27: Programa de muestreo y análisis de aguas residuales | F27: ='OOMRSC-05'!P57 -> SI | G27: ='OOMRSC-05'!Q57 -> 100
D28: Suburbano Técnico | E28: Cumplir con el volumen de agua potabilizada. | F28: ='OOMRSC-05'!P58 -> SI | G28: ='OOMRSC-05'!Q58 -> 1241188
C29: Técnica | D29: Control de Calidad | E29: Cumplir con las auditorías para la acreditación de la NMX-EC-17025-IMNC-2018 y/o ISO/IEC 17025:2017. | F29: ='OOMRSC-05'!P88 -> SI | G29: ='OOMRSC-05'!Q88 -> 1
D30: Alcantarillado y Saneamiento | E30: Índice de cumplimiento de reportes atendidos | F30: ='OOMRSC-05'!P89 -> SI | G30: ='OOMRSC-05'!Q89 -> 142
E31: Cumplimiento del programa de inspecciones | F31: ='OOMRSC-05'!P90 -> SI | G31: ='OOMRSC-05'!Q90 -> 100
D32: Suburbano Técnico | E32: Índice de atención a reportes suburbanos. | F32: ='OOMRSC-05'!P91 -> SI | G32: ='OOMRSC-05'!Q91 -> 103.22
F33: =COUNTIF(F16:F32,"si") -> 16 | G33: =F33/17 -> 0.94117647

Sheet Hoja2
B3: Meta MIR 2026
B4: Meta Anual | C4: 1er Trim. | D4: 2do Trim. | E4: 3er Trim. | F4: 4to Trim. | H4: LLENAR LO QUE ESTÁ EN AMARILLO
B5: 95 | C5: 24 | D5: 24 | E5: 24 | F5: 23
B7: Resultado Indicador Mensual
B8: Enero | C8: Febrero | D8: Marzo | E8: Abril | F8: Mayo | G8: Junio | H8: Julio | I8: Agosto | J8: Septiembre | K8: Octubre | L8: Noviembre | M8: Diciembre
B9: 100 | C9: 100 | D9: 100 | E9: 100 | F9: 100 | G9: 100
K10: LLENAR LO QUE ESTA EN AMARILLO
B11: Resultado de Indicadores (OP 12)
B12: 1er Trim. | D12: 2do Trim. | F12: 3er Trim. | H12: 4to Trim.
B13: Programada | C13: Real | D13: Programada | E13: Real | F13: Programada | G13: Real | H13: Programada | I13: Real
B14: =C5 -> 24 | C14: =(AVERAGE(B9:D9)*(C5))/B5 -> 25.263158 | D14: =C5+D5 -> 48 | E14: =((AVERAGE(E9:G9)*(D5))/B5)+C14 -> 50.526316 | F14: =C5+D5+E5 -> 72 | G14: =((AVERAGE(H9:J9)*(E5))/B5)+E14 -> #DIV/0! | H14: =C5+D5+E5+F5 -> 95 | I14: =((AVERAGE(K9:M9)*(F5))/B5)+G14 -> #DIV/0!

Sheet Hoja3
B3: Meta MIR 2026
B4: Meta Anual | C4: 1er Trim. | D4: 2do Trim. | E4: 3er Trim. | F4: 4to Trim. | H4: LLENAR LO QUE ESTÁ EN AMARILLO
B5: 90 | C5: 22 | D5: 23 | E5: 22 | F5: 23
B7: Resultado Indicador Mensual
B8: Enero | C8: Febrero | D8: Marzo | E8: Abril | F8: Mayo | G8: Junio | H8: Julio | I8: Agosto | J8: Septiembre | K8: Octubre | L8: Noviembre | M8: Diciembre
B9: na | C9: na | D9: 93 | E9: na | F9: na | G9: 93 | H9: na | I9: na | J9: 100 | K9: na | L9: na | M9: 100
K10: LLENAR LO QUE ESTA EN AMARILLO
B11: Resultado de Indicadores (OP 12)
B12: 1er Trim. | D12: 2do Trim. | F12: 3er Trim. | H12: 4to Trim.
B13: Programada | C13: Real | D13: Programada | E13: Real | F13: Programada | G13: Real | H13: Programada | I13: Real
B14: =C5 -> 22 | C14: =D9*C5/B5 -> 22.733333 | D14: =C5+D5 -> 45 | E14: =(G9*D5/B5)+C14 -> 46.5 | F14: =C5+D5+E5 -> 67 | G14: =(J9*E5/B5)+E14 -> 70.944444 | H14: =C5+D5+E5+F5 -> 90 | I14: =(M9*F5/B5)+G14 -> 96.5
