Workbook
Name ÁREAS_responsabilidad: 'ÁREAS QUE INTEGRAN PROCESOS'!$B$4:$B$8
Name Comercialización_e: 'ENTRADAS-SALIDAS DIAGRAMA'!$C$7
Name Comercialización_L: Comercialización[ÁREAS QUE INTEGRAN EL PROCESO:]
Name Comunicación_L: Comunicación[ÁREAS QUE INTEGRAN EL PROCESO:]
Name ESCUDO: INDEX('ENTRADAS-SALIDAS DIAGRAMA'!$J$59:$J$61,MATCH('ENTRADAS-SALIDAS DIAGRAMA'!$J$3,'ENTRADAS-SALIDAS DIAGRAMA'!$I$59:$I$61,0))
Name Gestión_de_recursos_L: Gestión_de_recursos[ÁREAS QUE INTEGRAN EL PROCESO:]
Name Mantenimiento_y_calibración_L: Mantenimiento_y_calibración[ÁREAS QUE INTEGRAN EL PROCESO:]
Name Medición_análisis_y_mejora_L: Medición_análisis_y_mejora[ÁREAS QUE INTEGRAN EL PROCESO:]
Name PROCESOS: 'MATRIZ REQUISITOS ISO'!$B$7:$B$14
Name Producción_L: Producción[ÁREAS QUE INTEGRAN EL PROCESO:]
Name Proyectos_e_infraestructura_L: Proyector_e_infraestructura[ÁREAS QUE INTEGRAN EL PROCESO:]
Name Responsabilidad_de_la_dirección_L: Responsabilidad_de_la_dirección[ÁREAS QUE INTEGRAN EL PROCESO:]

Sheet Matriz
E2: REQUISITOS NORMA ISO 9001/2015
B3: ENTRADAS | D3: PROCESO | E3: 4.1 | F3: 4.2 | G3: 4.3 | H3: 4.4 | I3: 5.1 | J3: 5.2 | K3: 5.3 | L3: 6.1 | M3: 6.2 | N3: 6.3 | O3: 7.1 | P3: 7.2 | Q3: 7.3 | R3: 7.4 | S3: 7.5 | T3: 8.1 | U3: 8.2 | V3: 8.3 | W3: 8.4 | X3: 8.5 | Y3: 8.6 | Z3: 8.7 | AA3: 9.1 | AB3: 9.2 | AC3: 9.3 | AD3: 10.1 | AE3: 10.2 | AF3: 10.3 | AH3: SALIDAS
B4: {=IFERROR(_xlfn._xlws.FILTER(ENTRADAS[ENTRADAS],ENTRADAS[PROCESO]=Matriz!D4),"")} | E4: {=IFERROR(IF(_xlfn.XLOOKUP($D$4,PROCESOS,'MATRIZ REQUISITOS ISO'!D7:AE14)=0,"",_xlfn.XLOOKUP($D$4,PROCESOS,'MATRIZ REQUISITOS ISO'!D7:AE14)),"")} | AH4: {=IFERROR(_xlfn._xlws.FILTER(SALIDAS[SALIDAS],SALIDAS[PROCESO]=Matriz!D4),"")} | DB4: =_xlfn.CONCAT(D4,"_L") -> _L
D5: ÁREA: | E5: PROPÓSITO DEL PROCESO:
E6: =IFERROR(IF(_xlfn.XLOOKUP($D$4,PROCESOS,'MATRIZ REQUISITOS ISO'!AG7:AG14)=0,"",_xlfn.XLOOKUP($D$4,PROCESOS,'MATRIZ REQUISITOS ISO'!AG7:AG14)),"")
D7: DOCUMENTOS QUE INTERACTUAN CON EL ÁREA(ACTUAR): | U7: VERIFICAR:
D8: =IF($D$4="","",IFERROR(IF($D$4="Responsabilidad_de_la_dirección",VLOOKUP($D$6,Responsabilidad_de_la_dirección[],3,0),IF($D$4="Mantenimiento_y_Calibración",VLOOKUP($D$6,Mantenimiento_y_calibración[],3,0),IF($D$4="Gestión_de_Recursos",VLOOKUP($D$6,Gestión_de_recursos[],3,0),IF($D$4="comercialización",VLOOKUP($D$6,Comercialización[],3,0),IF($D$4="Producción",VLOOKUP($D$6,Producción[],3,0),IF($D$4="Medición_Análisis_y_Mejora",VLOOKUP($D$6,Medición_análisis_y_mejora[],3,0),IF($D$4="Proyectos_e_Infraestructura",VLOOKUP($D$6,Proyector_e_infraestructura[],3,0),IF($D$4="Comunicación",VLOOKUP($D$6,Comunicación[],3,0))))))))),"Verificar área a buscar del proceso")) | U8: =+IF($D$4="","","NOTA: Los registros a “Verificar” se encuentran documentados en cada uno de los procedimientos de las áreas que participan en el “Actuar” de este anexo.")
D27: PROCESOS EN LOS QUE PARTICIPA EL ÁREA:
D28: {=IF($D$6="","",_xlfn._xlws.FILTER('ÁREAS QUE INTEGRAN PROCESOS'!AH:AH,'ÁREAS QUE INTEGRAN PROCESOS'!B:B=Matriz!$D$6))} | E28: =SUBSTITUTE(IF($D$6="","",_xlfn.CONCAT(D28,CHAR(10),D29,CHAR(10),D30,CHAR(10),D31,CHAR(10),D32,CHAR(10),D33,CHAR(10),D34,CHAR(10),D35)),"_"," ")
B47: Interacciones con el SGC | T47: =IF(D6="","",D6)
C49: Indicadores: | X49: TOTAL: | Z49: =COUNTIF(KPI[Área:],$T$47) -> 0
D50: {=IFERROR(_xlfn._xlws.FILTER(KPI[Indicador o Índice:],KPI[Área:]=Matriz!$T$47),"")}
C58: Matriz de comunicación: | X58: TOTAL: | Z58: =COUNTIF(COM[área:],$T$47) -> 0
D59: {=IFERROR(_xlfn._xlws.FILTER(COM[Aspecto a comunicar],COM[área:]=Matriz!$T$47),"")}
B71: Partes Interesadas:
D73: ID | E73: Requisito: | T73: Plan de acción:
D74: {=IFERROR(_xlfn._xlws.FILTER(PI[ID],PI[Área]=$T$47),"")} | L74: {=IFERROR(_xlfn._xlws.FILTER(PI[Requisito:],PI[Área]=$T$47),"")} | S74: {=IFERROR(_xlfn._xlws.FILTER(PI[Plan de acción],PI[Área]=$T$47),"")}
B96: Interacciones con el SGC | T96: =IF($D$6="","",$D$6)
C98: Organigrama: | X98: TOTAL:
K100: =IFERROR(_xlfn.XLOOKUP($T$96,ORG[área],ORG[imagen],,0),"")

Sheet Hoja2
A2: área | B2: imagen
A3: Alcantarillado y Saneamiento | B3: #VALUE!
A4: Atención Ciudadana
A5: Comunicación e Imagen Institucional | B5: #VALUE!
A6: Contabilidad | B6: #VALUE!
A7: Contratos y Servicios | B7: #VALUE!
A8: Control de Calidad | B8: #VALUE!
A9: Control y Servicios | B9: #VALUE!
A10: Informática | B10: #VALUE!
A11: Jurídico | B11: #VALUE!
A12: Licitaciones | B12: #VALUE!
A13: Línea OOMAPASC | B13: #VALUE!
A14: Mantenimiento de Redes | B14: #VALUE!
A15: Mantenimiento y Servicios Generales | B15: #VALUE!
A16: Órgano de Control Interno | B16: #VALUE!
... A30: Verificación y Lectura | B30: #VALUE!

Sheet Consulta Matriz Comunicación
B3: Área: | C3: Supervisión y Control de Obras
B6: Aspecto a comunicar | C6: Responsable de comunicar | D6: ¿A quién le comunica? | E6: ¿Cuándo comunica? | F6: Documentos | G6: Estrategias de comunicación
B7: {=IFERROR(_xlfn._xlws.FILTER(COM[[Aspecto a comunicar]:[Estrategias de comunicación]],COM[área:]=$C$3),"")} -> Cuando se inicie una obra. | C7: Gerencia de Supervisión y Control de Obras | D7: Subdirección de Mantenimiento de redes, Comunicación Social. | E7: Al momento de iniciar con la ejecución del contrato. | F7: Mediante oficio | G7: Medios electrónicos.
B8: Resultados de la revisión por la dirección. | C8: Gerente de Supervisión y Control de Obras | D8: Personal del área. | E8: Mensual | F8: OOMRSC-04 | G8: Correo Electrónico
B9: Cobro de Estimaciones | C9: Gerencia de Supervisión y Control de Obras | D9: Departamento de Tramites técnicos | E9: Al momento de autorizar una estimación. | F9: OOMXSO-01 OOMXSO-03 | G9: EXPEDIENTES
B10: Realización de convenios de monto, tiempo y conceptos | C10: Gerencia de Supervisión y Control de Obras | D10: Departamento de Licitaciones | E10: Al momento de que se requiera modificación | F10: OOMRCL- 16 OOMRCL-17 | G10: Físicamente y Medios electrónicos.
B11: Entrega de documentación | C11: Gerencia de Supervisión y Control de Obras | D11: Subdirección de Mantenimiento de Redes, Proyectos e Infraestructura | E11: Cuando se realice alguna actualización | F11: Plano de obra terminada, Oficio al área requirente | G11: Medios electrónicos.
B12: Cuando se termine una obra. | C12: Gerencia de Supervisión y Control de Obras | D12: Subdirección de Mantenimiento de redes, Comunicación Social. | E12: Al momento de terminación del contrato. | F12: Mediante oficio | G12: Medios electrónicos, correo electrónico.
B13: Realizar una conexión | C13: Gerencia de Supervisión y Control de Obras | D13: Subdirección de Mantenimiento de redes, Comunicación Social, CATEL. | E13: Al momento de requerir programar alguna conexión | F13: OOMRSO-17 OOMXSO-08 OOMXSO-09 | G13: Entrega de documentación físicamente
B14: Activación del patrimonio | C14: Gerencia de Supervisión y Control de Obras | D14: Contabilidad | E14: Al momento de recibir un fraccionamiento | F14: Mediante oficio y copia de Acta Entrega-Recepción | G14: Entrega de documentacion fisicamente y Correo electronico

Sheet Matriz Comunicación
A1: Dirección: | B1: área: | C1: Aspecto a comunicar | D1: Responsable de comunicar | E1: ¿A quién le comunica? | F1: ¿Cuándo comunica? | G1: Documentos | H1: Estrategias de comunicación
A2: Técnica | B2: Plantas Potabilizadoras | C2: Informe de resultados de los Indicadores de Calidad | D2: Gerente de Plantas Potabilizadoras | E2: A todo el personal de la Gerencia de las Plantas Potabilizadoras, al Sistema de Gestión de Calidad | F2: Mensual | G2: OOMPPP-29 OOMPPP-32 OOMPPP-34 OOMRPP-15 OOMRPP-16 OOMRPP-18 OOMRPP-19 OOMRPP-20 OOMRPP-21 OOMRPP-27 OOMRPP-28 OOMRPP-122 OOMRPP-131 | H2: Medios electrónicos, correo electrónico, WhatsApp, ZOOM, impresos en reuniones mensuales
A3: Técnica | B3: Plantas Potabilizadoras | C3: Informe de resultados de la auditoría interna. | D3: Gerente de Plantas Potabilizadoras | E3: A todo el personal de la Gerencia de las Plantas Potabilizadoras | F3: Cuando Auditan el área | G3: OOMRSC-16 | H3: Medios electrónicos, correo electrónico, WhatsApp, ZOOM, impresos en reuniones mensuales
A4: Técnica | B4: Plantas Potabilizadoras | C4: Avances y cumplimiento en FODA y MATRIZ DE RIESGOS | D4: Gerente de Plantas Potabilizadoras | E4: Auxiliar en control de documentos del SGC | F4: Mensual | G4: OOMRSC-36 OOMRSC-37 | H4: Revisión física.
A5: Técnica | B5: Plantas Potabilizadoras | C5: Resultados de la revisión por la dirección. | D5: Gerente de Plantas Potabilizadoras | E5: A todo el personal de la Gerencia de las Plantas Potabilizadoras | F5: Mensual | G5: OOMRSC-04 | H5: Medios electrónicos, correo electrónico, WhatsApp, ZOOM, impresos en reuniones mensuales
A6: Técnica | B6: Plantas Potabilizadoras | C6: Resultados de el ambiente de trabajo | D6: Gerente de Plantas Potabilizadoras | E6: A todo el personal de la Gerencia de las Plantas Potabilizadoras | F6: Anual | G6: Indicador de Recursos Humanos | H6: Medios electrónicos, correo electrónico, WhatsApp, ZOOM, impresos en reuniones mensuales
A7: Técnica | B7: Alcantarillado y Saneamiento | C7: Indicadores de Calidad | D7: Alcantarillado y Saneamiento | E7: SGC Y PERSONAL | F7: Mensual | G7: OOMRSC-03 Y OOMRSC-05 | H7: Medios electrónico y Formato Impreso
A8: Técnica | B8: Alcantarillado y Saneamiento | C8: Resultados de la revisión por la dirección. | D8: Gerente de Alcantarillado y Saneamiento. | E8: Personal del área. | F8: Mensual | G8: OOMRSC-04 | H8: Correo Electrónico
A9: Técnica | B9: Alcantarillado y Saneamiento | C9: Transparencia | D9: Alcantarillado y Saneamiento | E9: Transparencia y responsable de área de transparencia | F9: trimestral | G9: Ley general de transparencia y acceso a la información pública. | H9: Correo Electrónico
A10: Técnica | B10: Alcantarillado y Saneamiento | C10: PEMS | D10: Alcantarillado y Saneamiento | E10: Transparencia y responsable de área de transparencia | F10: TRIMESTRAL | G10: PEMS | H10: Correo Electrónico
A11: Técnica | B11: Alcantarillado y Saneamiento | C11: CONAGUA | D11: Alcantarillado y Saneamiento | E11: DECLARAGUA | F11: TRIMESTRAL | G11: OOMXGS-03 OOMXGS-04 | H11: SISTEMA DECLARAGUA Y SUBDIRECCION
A12: Técnica | B12: Alcantarillado y Saneamiento | C12: OP 12 | D12: Alcantarillado y Saneamiento | E12: CONTABILIDAD | F12: trimestral | G12: OP 12 | H12: Correo Electrónico
... A200: Programas Sociales | B200: Trabajo Social | C200: Se da de alta a los usuarios con apoyos de Insten y Discapacidad | D200: Auxiliar de Trabajo Social | E200: A los Auxiliares de Atención a usuarios, cajeros, auxiliares adtvos y a quienes ocupan el apoyo | F200: diario | G200: OOMRSS-11 | H200: la persona que realice el trámite lo entrega al departamento para su ingreso a Sistema Comercial

Sheet Partes interesadas
A1: ID | B1: Parte Interesada: | C1: Área | D1: Requisito: | E1: Plan de acción | F1: Periodicidad | G1: Norma o Ley que aplica:
A2: Producto | B2: USUARIO DEL AGUA | C2: Plantas Potabilizadoras | D2: TURBIEDAD | E2: OOMPPP-05 Control de Turbiedad plantas 1 y 2 | F2: Lo mencionado en procedimiento | G2: OOMEOR-03 NOM-127-SSA1-2021
A3: Producto | B3: USUARIO DEL AGUA | C3: Plantas Potabilizadoras | D3: TURBIEDAD | E3: OOMPPP-06 Control de Turbiedad plantas 3 y 4 | F3: Lo mencionado en procedimiento | G3: OOMEOR-03 NOM-127-SSA1-2021
A4: Producto | B4: USUARIO DEL AGUA | C4: Plantas Potabilizadoras | D4: TURBIEDAD | E4: OOMPPP-07 Control de Turbiedad planta V.B. | F4: Lo mencionado en procedimiento | G4: OOMEOR-03 NOM-127-SSA1-2021
A5: Producto | B5: USUARIO DEL AGUA | C5: Control de Calidad | D5: TURBIEDAD | E5: OOMPCC-01 Determinación de Turbiedad NOM-201-SSA1-2015 | F5: Lo mencionado en procedimiento | G5: OOMEOR-03 NOM-127-SSA1-2021
A6: Producto | B6: USUARIO DEL AGUA | C6: Suburbano Técnico | D6: TURBIEDAD | E6: OOMPTS-09 Control de Turbiedad en Sistemas Suburbanos | F6: Lo mencionado en procedimiento | G6: OOMEOR-03 NOM-127-SSA1-2021
A7: Producto | B7: USUARIO DEL AGUA | C7: Control de Calidad | D7: COLOR | E7: OOMPCC-04 Determinación de Color | F7: Lo mencionado en procedimiento | G7: OOMEOR-03 NOM-127-SSA1-2021
A8: Producto | B8: USUARIO DEL AGUA | C8: Suburbano Técnico | D8: COLOR | E8: OOMPTS-14 Control de Manganeso y Fierro en Sistemas Suburbanos | F8: Lo mencionado en procedimiento | G8: OOMEOR-03 NOM-127-SSA1-2021
A9: Producto | B9: USUARIO DEL AGUA | C9: Control de Calidad | D9: OLOR Y SABOR | E9: OOMPCC-09 Determinación de Olor y Sabor | F9: Lo mencionado en procedimiento | G9: NOM-127-SSA1-1994 (NOTA: Sirve como guía para cumplir con los parámetros de olor y sabor)
A10: Producto | B10: USUARIO DEL AGUA | C10: Plantas Potabilizadoras | D10: OLOR Y SABOR | E10: OOMPPP-26 Paro de Plantas por Olor fuera de Norma | F10: Lo mencionado en procedimiento | G10: NOM-127-SSA1-1994 (NOTA: Sirve como guía para cumplir con los parámetros de olor y sabor)
A11: Producto | B11: USUARIO DEL AGUA | C11: Plantas Potabilizadoras | D11: OLOR Y SABOR | E11: OOMPPP-28 Determinación de Olor y Sabor | F11: Lo mencionado en procedimiento | G11: NOM-127-SSA1-1994 (NOTA: Sirve como guía para cumplir con los parámetros de olor y sabor)
A12: Producto | B12: USUARIO DEL AGUA | C12: Suburbano Técnico | D12: OLOR Y SABOR | E12: OOMPTS-17 Determinación de Olor y Sabor en Sistemas Suburbanos | F12: Lo mencionado en procedimiento | G12: NOM-127-SSA1-1994 (NOTA: Sirve como guía para cumplir con los parámetros de olor y sabor)
... A37: Servicio | B37: USUARIO DEL AGUA | C37: ALCANTARILLADO Y SANEAMIENTO | D37: CONTROL DE DESCARGAS DE AGUAS RESIDUALES | E37: OOMPGS-01 Visitas de Inspección | F37: Lo mencionado en procedimiento | G37: OOMEOR-33 NOM - 002- SEMARNAT-1996; OOMEOR-21 Ley de Aguas del Estado de Sonora; OOMEOR-17 Ley de ingresos y presupuestos de egresos del ayuntamiento del municipio de Cajeme Sonora para el ejercicio fiscal vigente.
A38: Servicio | B38: USUARIO DEL AGUA | C38: ALCANTARILLADO Y SANEAMIENTO | D38: CONTROL DE DESCARGAS DE AGUAS RESIDUALES | E38: OOMPGS-02 Dictamen Técnico | F38: Lo mencionado en procedimiento
A39: Servicio | B39: USUARIO DEL AGUA | C39: ALCANTARILLADO Y SANEAMIENTO | D39: ATENCIÓN A USUARIOS | E39: OOMPGS-06 Atención a Reportes de Alcantarillado Sanitario | F39: Lo mencionado en procedimiento | G39: OOMEOR-22 Ley de Obras Públicas y Servicios relacionados con las mismas para el Estado de Sonora, OOMEOR-26 Reglamento de la Ley de Obras Públicas y Servicios Relacionados con las Mismas para el Estado de Sonora; OOMEOR-21 Ley de Aguas del Estado de Sonora
A40: Servicio | B40: USUARIO DEL AGUA | C40: Suburbano Técnico | D40: ATENCIÓN A USUARIOS DEL SISTEMA DE ALCANTARILLADO | E40: OOMPTS-07 Atención a Reportes de Drenaje Tapados Suburbano | F40: Lo mencionado en procedimiento | G40: OOMEOR-22 Ley de Obras Públicas y Servicios relacionados con las mismas para el Estado de Sonora, OOMEOR-26 Reglamento de la Ley de Obras Públicas y Servicios Relacionados con las Mismas para el Estado de Sonora; OOMEOR-21 Ley de Aguas del Estado de Sonor
A41: Servicio | B41: USUARIO DEL AGUA | C41: Jurídico | D41: INCUMPLIMIENTO A LA LEGISLACIÓN | E41: OOMPJU-05 Sanción | F41: Lo mencionado en procedimiento | G41: OOMEOR-21 Ley de Agua del Estado de Sonora, OOMEOR-33 Nom-002-Semarnat-1996
A42: Servicio | B42: USUARIO DEL AGUA | C42: Jurídico | D42: QUEJAS PROFECO | E42: OOMPJU-11 Contestación de quejas profeco | F42: Lo mencionado en procedimiento | G42: OOMEOR-122 Ley Federal de Protección al Consumidor
A43: Servicio | B43: USUARIO DEL AGUA | C43: TRÁMITES TÉCNICOS | D43: ALTA DE FRACCIONAMIENTOS | E43: OOMPTT-01 Alta de Fraccionamiento | F43: Lo mencionado en procedimiento | G43: OOMEOR-85 Ley de ordenamiento territorial y desarrollo urbano del Estado de Sonora
A44: Servicio | B44: USUARIO DEL AGUA | C44: CONTRATOS Y SERVICIOS | D44: ATENCIÓN A USUARIOS MODULO | F44: Lo mencionado en procedimiento | G44: OOMEOR-21 Ley de Aguas del Estado Sonora, OOMEOR-17 Ley de ingresos y presupuestos de egresos del ayuntamiento del municipio de Cajeme Sonora para el ejercicio fiscal vigente.
A45: Servicio | B45: USUARIO DEL AGUA | C45: CONTRATOS Y SERVICIOS | D45: CONTRATACIÓN DE TOMA DE AGUA Y DESCARGA | E45: OOMPGC-01 Contratación de Instalación de Cuadro, Toma de Agua, Registro Descarga Sanitaria | F45: Lo mencionado en procedimiento | G45: OOMEOR-21 Ley de Aguas del Estado Sonora, OOMEOR-17 Ley de ingresos y presupuestos de egresos del ayuntamiento del municipio de Cajeme Sonora para el ejercicio fiscal vigente.
A46: Servicio | B46: USUARIO DEL AGUA | C46: CONTRATOS Y SERVICIOS | D46: CONTRATACIÓN DE TOMA DE AGUA Y DESCARGA | F46: Lo mencionado en procedimiento | G46: OOMEOR-21 Ley de Aguas del Estado Sonora, OOMEOR-17 Ley de ingresos y presupuestos de egresos del ayuntamiento del municipio de Cajeme Sonora para el ejercicio fiscal vigente.
A47: Servicio | B47: USUARIO DEL AGUA | C47: CONTRATOS Y SERVICIOS | D47: FACTURACIÓN | E47: OOMPGC- 03 Cambio de nombre en facuración | F47: Lo mencionado en procedimiento | G47: OOMEOR-21 Ley de Aguas del Estado Sonora, OOMEOR-17 Ley de ingresos y presupuestos de egresos del ayuntamiento del municipio de Cajeme Sonora para el ejercicio fiscal vigente.
A48: Servicio | B48: USUARIO DEL AGUA | C48: CONTRATOS Y SERVICIOS | D48: CONVENIOS | E48: OOMPGC- 04 Convenio | F48: Lo mencionado en procedimiento | G48: OOMEOR-21 Ley de Aguas del Estado Sonora, OOMEOR-17 Ley de ingresos y presupuestos de egresos del ayuntamiento del municipio de Cajeme Sonora para el ejercicio fiscal vigente.
A49: Servicio | B49: USUARIO DEL AGUA | C49: CONTRATOS Y SERVICIOS | D49: CERTIFICADOS | E49: OOMPGC-05 Certificado de no adeudo | F49: Lo mencionado en procedimiento | G49: OOMEOR-21 Ley de Aguas del Estado Sonora, OOMEOR-17 Ley de ingresos y presupuestos de egresos del ayuntamiento del municipio de Cajeme Sonora para el ejercicio fiscal vigente.
A50: Servicio | B50: USUARIO DEL AGUA | C50: CONTRATOS Y SERVICIOS | D50: ALTA DE SERVICIOS | E50: OOMPGC-06 Alta de Servicio | F50: Lo mencionado en procedimiento | G50: OOMEOR-21 Ley de Aguas del Estado Sonora, OOMEOR-17 Ley de ingresos y presupuestos de egresos del ayuntamiento del municipio de Cajeme Sonora para el ejercicio fiscal vigente.
A51: Servicio | B51: USUARIO DEL AGUA | C51: CONTRATOS Y SERVICIOS | D51: CONTRATACIÓN DE MEDIDORES | E51: OOMPGC-08 Contratación de Medidores | F51: Lo mencionado en procedimiento | G51: OOMEOR-21 Ley de Aguas del Estado Sonora, OOMEOR-17 Ley de ingresos y presupuestos de egresos del ayuntamiento del municipio de Cajeme Sonora para el ejercicio fiscal vigente.
A52: Servicio | B52: USUARIO DEL AGUA | C52: CONTRATOS Y SERVICIOS | D52: CAMBIOS DE TOMA | E52: OOMPGC-11 Cambio de Toma Activa a Toma Muerta | F52: Lo mencionado en procedimiento | G52: OOMEOR-21 Ley de Aguas del Estado Sonora, OOMEOR-17 Ley de ingresos y presupuestos de egresos del ayuntamiento del municipio de Cajeme Sonora para el ejercicio fiscal vigente.
A53: Servicio | B53: USUARIO DEL AGUA | C53: CONTRATOS Y SERVICIOS | D53: CAMBIOS DE TOMA | E53: OOMPGC-12 Cambio de Toma Muerta a Toma Activa | F53: Lo mencionado en procedimiento | G53: OOMEOR-21 Ley de Aguas del Estado Sonora, OOMEOR-17 Ley de ingresos y presupuestos de egresos del ayuntamiento del municipio de Cajeme Sonora para el ejercicio fiscal vigente.
A54: Servicio | B54: USUARIO DEL AGUA | C54: CONTRATOS Y SERVICIOS | D54: ESTADOS DE CUENTA | E54: OOMIGC-02 Expedir Estados de Cuenta | F54: Lo mencionado en procedimiento | G54: OOMEOR-21 Ley de Aguas del Estado Sonora, OOMEOR-17 Ley de ingresos y presupuestos de egresos del ayuntamiento del municipio de Cajeme Sonora para el ejercicio fiscal vigente.
A55: Servicio | B55: USUARIO DEL AGUA | C55: CONTRATOS Y SERVICIOS | D55: DERECHOS DE CONEXIÓN | E55: OOMIGC-03 Cargos de Derecho de Conexión para Constructoras | F55: Lo mencionado en procedimiento | G55: OOMEOR-21 Ley de Aguas del Estado Sonora, OOMEOR-17 Ley de ingresos y presupuestos de egresos del ayuntamiento del municipio de Cajeme Sonora para el ejercicio fiscal vigente.
A56: Servicio | B56: USUARIO DEL AGUA | C56: CONTRATOS Y SERVICIOS | D56: COBROS | E56: OOMPGC-16 Cobros en Caja | F56: Lo mencionado en procedimiento | G56: OOMEOR-21 Ley de Aguas del Estado Sonora, OOMEOR-17 Ley de ingresos y presupuestos de egresos del ayuntamiento del municipio de Cajeme Sonora para el ejercicio fiscal vigente.
A57: Servicio | B57: USUARIO DEL AGUA | C57: Atención Ciudadana | D57: DOMICILIACIÓN | E57: OOMPAC-02 Domiciliación de Pagos | F57: Lo mencionado en procedimiento | G57: OOMEOR-21 Ley de Aguas del Estado Sonora, OOMEOR-17 Ley de ingresos y presupuestos de egresos del ayuntamiento del municipio de Cajeme Sonora para el ejercicio fiscal vigente.
A58: Servicio | B58: USUARIO DEL AGUA | C58: VERIFICACIÓN Y LECTURA | D58: MICROMEDICIÓN | E58: OOMPVL-02 Procedimiento de Micromedición | F58: Lo mencionado en procedimiento | G58: OOMEOR-21 Ley de Aguas del Estado Sonora, OOMEOR-17 Ley de ingresos y presupuestos de egresos del ayuntamiento del municipio de Cajeme Sonora para el ejercicio fiscal vigente.
... A65: Servicio | B65: USUARIO DEL AGUA | C65: CONTROL Y SERVICIOS | D65: CAMBIOS DE TOMA | E65: OOMICS-02 Cambio de Toma Activa a Toma Muerta | F65: Lo mencionado en procedimiento | G65: OOMEOR-21 Ley de Aguas del Estado Sonora, OOMEOR-17 Ley de ingresos y presupuestos de egresos del ayuntamiento del municipio de Cajeme Sonora para el ejercicio fiscal vigente.
A66: Servicio | B66: USUARIO DEL AGUA | C66: CONTROL Y SERVICIOS | D66: CAMBIOS DE TOMA | F66: Lo mencionado en procedimiento | G66: OOMEOR-21 Ley de Aguas del Estado Sonora, OOMEOR-17 Ley de ingresos y presupuestos de egresos del ayuntamiento del municipio de Cajeme Sonora para el ejercicio fiscal vigente.
A67: Servicio | B67: USUARIO DEL AGUA | C67: Línea OOMAPASC | D67: ATENCIÓN A USUARIOS LÍNEA OOMAPASC | E67: OOMPAT-08 Generacion de reportes | F67: Lo mencionado en procedimiento | G67: OOMEOR-21 Ley de Aguas del Estado Sonora, OOMEOR-17 Ley de ingresos y presupuestos de egresos del ayuntamiento del municipio de Cajeme Sonora para el ejercicio fiscal vigente.
A68: Servicio | B68: USUARIO DEL AGUA | C68: Línea OOMAPASC | D68: ATENCIÓN A USUARIOS LÍNEA OOMAPASC | E68: OOMPAT-13 Atención de auxiliar telefonico a usuarios | F68: Lo mencionado en procedimiento | G68: OOMEOR-21 Ley de Aguas del Estado Sonora, OOMEOR-17 Ley de ingresos y presupuestos de egresos del ayuntamiento del municipio de Cajeme Sonora para el ejercicio fiscal vigente.
A69: Servicio | B69: USUARIO DEL AGUA | C69: TRABAJO SOCIAL | D69: Estudios Socioeconomicos | E69: OOMPSS-01 Apoyos o Subsidios en adeudos de consumo o contratación de servicios. | F69: Lo mencionado en procedimiento | G69: OOMEOR-17 Ley de Ingresos y presupuestos de egresos del Ayuntamiento del Municipio de Cajeme Sonora OOMEOR-21 Ley de Aguas del Estado Sonora
A70: Servicio | B70: USUARIO DEL AGUA | C70: MANTENIMIENTO DE REDES | D70: REHABILITACIÓN DE INFRAESTRUCTURA | E70: OOMPMR-01 Procedimiento General de Supervisión de Redes de Agua Potable y Obras de Reparación Asignadas a Contratistas. | F70: Lo mencionado en procedimiento | G70: OOMEOR-22 Ley de Obras Públicas y Servicios relacionados con las mismas para el Estado de Sonora, OOMEOR-26 Reglamento de la Ley de Obras Públicas y Servicios Relacionados con las Mismas para el Estado de Sonora; OOMEOR-21 Ley de Aguas del Estado de Sonora. OOMEOR-14 Ley de Adquisiciones Arrendamientos y Servicios del Sector Público, OOMEOR-15 Reglamento de la Ley de Adquisiciones Arrendamientos y Servicios del Sector Público
...

Sheet KPI-2025
A1: Proceso: | B1: Dirección: | C1: Área: | D1: # | E1: Indicador o Índice: | F1: Periodicidad | G1: Unidad de Medida
A2: Responsabilidad de la Dirección | B2: General | C2: Sistema de Gestión de Calidad | D2: 0 | E2: Lograr el grado de eficacia del SGC determinado por auditorías e indicadores. | F2: Mensual | G2: Porcentaje
A3: Responsabilidad de la Dirección | B3: General | C3: Dirección General | D3: 1 | E3: Cumplir con las metas establecidas por las direcciones adscritas a la Dirección General | F3: Trimestral | G3: Porcentaje | L3: {=_xlfn.UNIQUE(KPI[Área:])} -> Sistema de Gestión de Calidad | M3: =COUNTIF(KPI[Área:],L3) -> 5
A4: Responsabilidad de la Dirección | B4: General | C4: Dirección General | D4: 2 | E4: Mantener una relación de comunicación con el Consejo Consultivo. | F4: Trimestral | G4: Actas | L4: Dirección General | M4: =COUNTIF(KPI[Área:],L4) -> 2
A5: Gestión de Recursos | B5: Administrativa | C5: Recursos Humanos | D5: 3 | E5: Remuneración del personal. | F5: Trimestral | G5: Cantidad | L5: Recursos Humanos | M5: =COUNTIF(KPI[Área:],L5) -> 4
A6: Gestión de Recursos | B6: Administrativa | C6: Recursos Humanos | D6: 4 | E6: Remuneración a jubilados y pensionados | F6: Trimestral | G6: Cantidad | L6: Recursos Materiales | M6: =COUNTIF(KPI[Área:],L6) -> 2
A7: Gestión de Recursos | B7: Administrativa | C7: Recursos Humanos | D7: 5 | E7: Cumplir con el programa trimestral de capacitación. | F7: Trimestral | G7: Porcentaje | L7: Contabilidad | M7: =COUNTIF(KPI[Área:],L7) -> 1
A8: Gestión de Recursos | B8: Administrativa | C8: Recursos Humanos | D8: 6 | E8: Evaluación del ambiente de trabajo. | F8: Mensual | G8: Porcentaje | L8: Seguridad Industrial | M8: =COUNTIF(KPI[Área:],L8) -> 3
A9: Gestión de Recursos | B9: Administrativa | C9: Recursos Materiales | D9: 7 | E9: Evaluar el desempeño de proveedores de productos químicos críticos | F9: Mensual | G9: Porcentaje | L9: Licitaciones | M9: =COUNTIF(KPI[Área:],L9) -> 2
A10: Gestión de Recursos | B10: Administrativa | C10: Recursos Materiales | D10: 8 | E10: Atender las solicitudes de compra en el tiempo establecido. | F10: Mensual | G10: Porcentaje | L10: Trámites Técnicos | M10: =COUNTIF(KPI[Área:],L10) -> 3
A11: Gestión de Recursos | B11: Administrativa | C11: Contabilidad | D11: 9 | E11: Cumplir con el calendario contable y presupuestal. | F11: Mensual | G11: Documentos | L11: Informática | M11: =COUNTIF(KPI[Área:],L11) -> 3
A12: Gestión de Recursos | B12: Administrativa | C12: Seguridad Industrial | D12: 10 | E12: Accidentes de trabajo | F12: Mensual | G12: Cantidad | L12: Mantenimiento y Servicios Generales | M12: =COUNTIF(KPI[Área:],L12) -> 6
A13: Gestión de Recursos | B13: Administrativa | C13: Licitaciones | D13: 11 | E13: Cumplir con el proceso de licitación pública o simplificada | F13: Mensual | G13: Porcentaje | L13: Mantenimiento de Redes | M13: =COUNTIF(KPI[Área:],L13) -> 1
A14: Gestión de Recursos | B14: Administrativa | C14: Licitaciones | D14: 12 | E14: Cumplir con el proceso de adjudicación directa. | F14: Mensual | G14: Porcentaje | L14: Control de Calidad | M14: =COUNTIF(KPI[Área:],L14) -> 4
A15: Gestión de Recursos | B15: Técnica | C15: Trámites Técnicos | D15: 13 | E15: Índice de programas federales gestionados | F15: Semestral | G15: Programa | L15: Plantas Potabilizadoras | M15: =COUNTIF(KPI[Área:],L15) -> 3
... A36: Comercialización | B36: Comercial | C36: Verificación y Lectura | D36: 34 | E36: Porcentaje de error en toma de lectura. | F36: Mensual | G36: Porcentaje | L36: Comunicación e imagen institucional | M36: =COUNTIF(KPI[Área:],L36) -> 3
A37: Comercialización | B37: Comercial | C37: Verificación y Lectura | D37: 35 | E37: Cobertura de Micromedición en área urbana | F37: Mensual | G37: Porcentaje | M37: =COUNTIF(KPI[Área:],L37) -> 0
A38: Comercialización | B38: Comercial | C38: Suburbano Comercial | D38: 36 | E38: Cumplir con el presupuesto de ingresos en la gerencia Providencia. | F38: Mensual | G38: Porcentaje | M38: =COUNTIF(KPI[Área:],L38) -> 0
A39: Comercialización | B39: Comercial | C39: Suburbano Comercial | D39: 37 | E39: Cumplir con el presupuesto de ingresos en la gerencia Esperanza | F39: Mensual | G39: Porcentaje | M39: =COUNTIF(KPI[Área:],L39) -> 0
A40: Comercialización | B40: Comercial | C40: Suburbano Comercial | D40: 38 | E40: Cumplir con el presupuesto de ingresos en la gerencia Pueblo Yaqui. | F40: Mensual | G40: Porcentaje | M40: =COUNTIF(KPI[Área:],L40) -> 0
A41: Comercialización | B41: Comercial | C41: Suburbano Comercial | D41: 39 | E41: Cumplir con el presupuesto de ingresos en la gerencia Marte R. Gómez. | F41: Mensual | G41: Porcentaje
A42: Comercialización | B42: Comercial | C42: Dirección Comercial | D42: 40 | E42: Cumplir con el presupuesto programado de ingresos. | F42: Mensual | G42: Porcentaje
A43: Comercialización | B43: Comercial | C43: Dirección Comercial | D43: 41 | E43: Eficiencia comercial | F43: Mensual | G43: Porcentaje
A44: Comercialización | B44: Comercial | C44: Dirección Comercial | D44: 42 | E44: Eficiencia comercial de rezago | F44: Mensual | G44: Porcentaje
A45: Comercialización | B45: Programas Sociales | C45: Trabajo Social | D45: 43 | E45: Atender las órdenes de trabajo en un lapso de 7 días hábiles | F45: Mensual | G45: Porcentaje
A46: Producción | B46: Técnica | C46: Control de Calidad | D46: 44 | E46: Cumplimiento a NOM-127-SSA1-2021 aplicable a control de calidad. | F46: Mensual | G46: Muestreos
A47: Producción | B47: Técnica | C47: Control de Calidad | D47: 45 | E47: Índice de cumplimiento en muestreos y análisis de agua potable. | F47: Trimestral | G47: Informes
A48: Producción | B48: Técnica | C48: Plantas Potabilizadoras | D48: 46 | E48: Producción de agua en plantas potabilizadoras y pozos de área urbana | F48: Mensual | G48: M3
A49: Producción | B49: Técnica | C49: Plantas Potabilizadoras | D49: 47 | E49: Índice de cobertura de macromedición | F49: Mensual | G49: Porcentaje
A50: Producción | B50: Técnica | C50: Alcantarillado y Saneamiento | D50: 48 | E50: Índice de agua residual tratada. | F50: Mensual | G50: Porcentaje
A51: Producción | B51: Técnica | C51: Alcantarillado y Saneamiento | D51: 49 | E51: Programa de muestreo y análisis de aguas residuales | F51: Mensual | G51: Porcentaje
A52: Producción | B52: Técnica | C52: Suburbano Técnico | D52: 50 | E52: Cumplir con el volumen de agua potabilizada. | F52: Mensual | G52: M3
... A103: Comunicación | B103: Programas Sociales | C103: Trabajo Social | D103: 101 | E103: Cumplir con el programa anual de pláticas de cultura del agua. | F103: Mensual | G103: Porcentaje

Sheet Hoja4
A1: Alcantarillado y Saneamiento
A2: Atención Ciudadana
A3: Comunicación e Imagen Institucional
A4: Contabilidad
A5: Contratos y Servicios
A6: Control de Calidad
A7: Control y Servicios
A8: Informática
A9: Jurídico
A10: Licitaciones
A11: Línea OOMAPASC
A12: Mantenimiento de Redes
... A30: Verificación y Lectura

Sheet Interacción entre procesos
B2: OOMAPASC | D2: MATRIZ DE PROCESOS | L2: Fecha actualización: | O2: 46235
L3: Clave: | O3: OOMLSC-A21
L4: Revisión: | O4: 15

Sheet MATRIZ REQUISITOS ISO
B6: PROCESOS | C6: LISTA BUSQUEDA | D6: 4.1 | E6: 4.2 | F6: 4.3 | G6: 4.4 | H6: 5.1 | I6: 5.2 | J6: 5.3 | K6: 6.1 | L6: 6.2 | M6: 6.3 | N6: 7.1 | O6: 7.2 | P6: 7.3 | Q6: 7.4 | R6: 7.5 | S6: 8.1 | T6: 8.2 | U6: 8.3 | V6: 8.4 | W6: 8.5 | X6: 8.6 | Y6: 8.7 | Z6: 9.1 | AA6: 9.2 | AB6: 9.3 | AC6: 10.1 | AD6: 10.2 | AE6: 10.3 | AF6: TOTAL REQUISITOS | AG6: PROPÓSITO DE LOS PROCESOS
A7: 1 | B7: Comercialización | C7: =_xlfn.CONCAT(B7&"_L") -> Comercialización_L | E7: 4 | G7: 4 | K7: 4 | L7: 4 | N7: 4 | O7: 4 | P7: 4 | Q7: 4 | R7: 4 | S7: 4 | T7: 4 | W7: 4 | X7: 4 | Y7: 4 | Z7: 4 | AB7: 4 | AC7: 4 | AD7: 4 | AE7: 4 | AF7: =COUNT(D7:AE7) -> 19 | AG7: El OOMAPAS de Cajeme lleva a cabo actividades de comercialización con sus clientes, donde determina las actividades para el servicio que se ofrece y mide la eficiencia de sus resultados. En este proceso es donde se define las actividades para la recaudación y sus estrategias de cobranza tanto en zona urbana como suburbana.
A8: 2 | B8: Comunicación | C8: =_xlfn.CONCAT(B8&"_L") -> Comunicación_L | D8: 8 | E8: 8 | G8: 8 | K8: 8 | L8: 8 | N8: 8 | P8: 8 | Q8: 8 | R8: 8 | Z8: 8 | AA8: 8 | AB8: 8 | AC8: 8 | AD8: 8 | AE8: 8 | AF8: =COUNT(D8:AE8) -> 15 | AG8: En este proceso se lleva a cabo la comunicación con el cliente interno, externo y las partes interesadas, por medio de correos, tableros, intranet, en conjunto con la información de los reportes para dar servicio a los usuarios que envía el H. Ayuntamiento de Cajeme.
A9: 3 | B9: Gestión_de_Recursos | C9: =_xlfn.CONCAT(B9&"_L") -> Gestión_de_Recursos_L | G9: 2 | K9: 2 | L9: 2 | N9: 2 | O9: 2 | P9: 2 | Q9: 2 | R9: 2 | V9: 2 | Y9: 2 | Z9: 2 | AB9: 2 | AC9: 2 | AD9: 2 | AE9: 2 | AF9: =COUNT(D9:AE9) -> 15 | AG9: En este proceso se Gestiona tanto los recursos materiales, recursos financieros, recurso humano y recursos federales; necesarios para la producción de agua potable, saneamiento y alcantarillado y los servicios comerciales.
A10: 4 | B10: Mantenimiento_y_Calibración | C10: =_xlfn.CONCAT(B10&"_L") -> Mantenimiento_y_Calibración_L | G10: 3 | K10: 3 | L10: 3 | N10: 3 | O10: 3 | P10: 3 | Q10: 3 | R10: 3 | W10: 3 | Y10: 3 | Z10: 3 | AB10: 3 | AC10: 3 | AD10: 3 | AE10: 3 | AF10: =COUNT(D10:AE10) -> 15 | AG10: El OOMAPAS de Cajeme establece procesos para asegurarse de que el seguimiento y medición pueden realizarse de una manera coherente con los requisitos de seguimiento y medición. Cuando es necesario asegurarse de la validez de los resultados, el equipo de medición se calibra o verifica, o ambos, a intervalos especificados o antes de su utilización, comparado con patrones de medición trazables a patrones de mediciones nacionales o internacionales; cuando no existen tales patrones se registran la base utilizada para la calibración y verificación. En este proceso se llevan a cabo programas de mantenimientos preventivos para los equipos y la infraestructura del organismo.
A11: 5 | B11: Medición_Análisis_y_Mejora | C11: =_xlfn.CONCAT(B11&"_L") -> Medición_Análisis_y_Mejora_L | D11: 6 | E11: 6 | G11: 6 | K11: 6 | L11: 6 | O11: 6 | P11: 6 | Q11: 6 | R11: 6 | Y11: 6 | Z11: 6 | AA11: 6 | AB11: 6 | AC11: 6 | AD11: 6 | AE11: 6 | AF11: =COUNT(D11:AE11) -> 16 | AG11: El OOMAPAS de Cajeme Planifica e implementa los procesos de seguimiento, medición, análisis y mejora necesarios para demostrar la conformidad con los requisitos del producto, asegurarse de la conformidad del Sistema de Gestión de la Calidad por medio de la Revisión por la Dirección y la realización de auditorías, y mejorar continuamente la eficacia del Sistema de Gestión de la Calidad. En este proceso se revisan los resultados de todas las actividades documentadas del Organismo, además de proporcionar el resultado de indicadores y de auditorias internas.
A12: 6 | B12: Producción | C12: =_xlfn.CONCAT(B12&"_L") -> Producción_L | E12: 5 | G12: 5 | K12: 5 | L12: 5 | N12: 5 | O12: 5 | P12: 5 | Q12: 5 | R12: 5 | S12: 5 | T12: 5 | W12: 5 | X12: 5 | Y12: 5 | Z12: 5 | AB12: 5 | AC12: 5 | AD12: 5 | AE12: 5 | AF12: =COUNT(D12:AE12) -> 19 | AG12: El OOMAPAS de Cajeme planifica y lleva a cabo la producción y la prestación del servicio bajo condiciones controladas. Las condiciones controladas incluyen cuando sea aplicable la disponibilidad de información que describe las características del producto, la disponibilidad de instrucciones de trabajo cuando es necesario, el uso del equipo apropiado y la implementación de actividades de liberación, entrega y posteriores a la entrega del producto. En este proceso se definen las actividades para el desarrollo del producto (agua potable, alcantarillado y saneamiento) principalmente.
A13: 7 | B13: Proyectos_e_Infraestructura | C13: =_xlfn.CONCAT(B13&"_L") -> Proyectos_e_Infraestructura_L | E13: 7 | G13: 7 | K13: 7 | L13: 7 | N13: 7 | O13: 7 | P13: 7 | Q13: 7 | R13: 7 | Y13: 7 | Z13: 7 | AB13: 7 | AC13: 7 | AD13: 7 | AE13: 7 | AF13: =COUNT(D13:AE13) -> 15 | AG13: En este proceso se desarrollan las propuestas de las obras de infraestructura hidráulica necesarias para las redes de agua potable, alcantarillado y saneamiento, con el apoyo de los programas federales, así como la infraestructura para los fraccionamientos y obras que van de la mano con el H. Ayuntamiento de Cajeme.
A14: 8 | B14: Responsabilidad_de_la_Dirección | C14: =_xlfn.CONCAT(B14&"_L") -> Responsabilidad_de_la_Dirección_L | D14: 1 | E14: 1 | F14: 1 | G14: 1 | H14: 1 | I14: 1 | J14: 1 | K14: 1 | L14: 1 | M14: 1 | N14: 1 | O14: 1 | P14: 1 | Q14: 1 | R14: 1 | S14: 1 | T14: 1 | Y14: 1 | Z14: 1 | AB14: 1 | AF14: =COUNT(D14:AE14) -> 20 | AG14: La alta dirección del OOMAPAS de Cajeme proporciona evidencia de su compromiso con el desarrollo e implementación del Sistema de Gestión de la Calidad, así como con la mejora continua de su eficacia. Comunica a la organización la importancia de satisfacer tanto los requisitos de las partes interesadas como los legales y reglamentarios, establece la política de la calidad, asegura que se establecen los objetivos de la calidad, lleva a cabo Revisiones por la Dirección y asegura la disponibilidad de los recursos.

Sheet ENTRADAS-SALIDAS DIAGRAMA
B3: PROCESO | C3: ENTRADAS | E3: PROCESO | F3: SALIDAS
B4: Responsabilidad_de_la_Dirección | C4: El estado de las acciones de las revisiones por la dirección previas. | E4: Responsabilidad_de_la_Dirección | F4: Las oportunidades de mejora.
B5: Responsabilidad_de_la_Dirección | C5: Los cambios en las cuestiones externas e internas que sean pertinentes al sistema de gestión de calidad. | E5: Responsabilidad_de_la_Dirección | F5: Cualquier necesidad de cambio en el sistema de gestión de calidad.
B6: Responsabilidad_de_la_Dirección | C6: La información sobre el desempeño y la eficacia del sistema de gestión de la calidad. | E6: Responsabilidad_de_la_Dirección | F6: Las necesidades de Recursos. | P6: =INDEX($J$59:$J$61,MATCH($J$3,$I$59:$I$61,0)) -> #N/A
B7: Responsabilidad_de_la_Dirección | C7: La adecuación de los recursos. | E7: Responsabilidad_de_la_Dirección | F7: Planificación de Cambios. | R7: =#REF! -> #REF!
B8: Responsabilidad_de_la_Dirección | C8: La eficacia de las acciones tomadas para abordar los riesgos y las oportunidades. | E8: Responsabilidad_de_la_Dirección | F8: Información solicitada por las partes interesadas Internas y Externas -CEA CONAGUA-
B9: Responsabilidad_de_la_Dirección | C9: Las oportunidades de mejora e Información de los Resultados. | E9: Responsabilidad_de_la_Dirección
B10: Gestión_de_Recursos | C10: Necesidad de Mejora a Proceso/Producto. Solicitud de Materiales y Servicios. Retroalimentación del Cliente. | E10: Gestión_de_Recursos | F10: Producto o Servicio Entregado. Recursos Externos Gestionados.
B11: Gestión_de_Recursos | C11: Retroalimentación del Cliente. Información de Proveedores. Política de Calidad. | E11: Gestión_de_Recursos | F11: Avance Presupuestal. Cheque o transferencia bancaria.
B12: Gestión_de_Recursos | C12: Objetivos de Calidad. Mejoras al Proceso. Solicitud de capacitación. | E12: Gestión_de_Recursos | F12: Bienes resguardados. Proveedores Contratados.
B13: Gestión_de_Recursos | C13: Presupuesto de egresos. Presupuesto de Ingresos. Necesidad de Recursos. | E13: Gestión_de_Recursos | F13: Proveedores Evaluados. Presupuesto Ejercido.
B14: Gestión_de_Recursos | C14: Apoyos/Subsidios Externos. Información interna de Evaluación a Proveedores. | E14: Gestión_de_Recursos | F14: Ampliaciones al Presupuesto.
B15: Gestión_de_Recursos | C15: Programa de inversión. Resultados de análisis de Productos Químicos/ Críticos. Normatividad Mexicana. | E15: Gestión_de_Recursos | F15: Producto Aceptado o Rechazado.
B16: Mantenimiento_y_Calibración | C16: Política de calidad. Objetivos de calidad. | E16: Mantenimiento_y_Calibración | F16: Mantenimiento preventivo y correctivo efectuado.
B17: Mantenimiento_y_Calibración | C17: Bitácora de mantenimiento. Programa de mantenimiento preventivo. | E17: Mantenimiento_y_Calibración | F17: Información para evaluación.
B18: Mantenimiento_y_Calibración | C18: Programa de mantenimiento de infraestructura de plantas y oficinas. | E18: Mantenimiento_y_Calibración | F18: Servicios proporcionados.
B19: Mantenimiento_y_Calibración | C19: Mantenimiento correctivo. | E19: Mantenimiento_y_Calibración | F19: Equipos disponibles.
B20: Mantenimiento_y_Calibración | C20: Recursos proporcionados. Mejoras al proceso. | E20: Mantenimiento_y_Calibración | F20: Desempeño del proceso.
B21: Mantenimiento_y_Calibración | C21: Análisis FODA. Matriz de Riesgos y oportunidades. | E21: Mantenimiento_y_Calibración | F21: Necesidad de recursos.
... B32: Producción | C32: Análisis FODA. Matriz de Riesgos y Oportunidades. | E32: Producción | F32: Mejora al producto. Mejora al proceso.
B33: Producción | E33: Producción | F33: Cumplimiento a Normas Oficiales.
B34: Medición_Análisis_y_Mejora | C34: Política de Calidad Objetivos de Calidad | E34: Medición_Análisis_y_Mejora | F34: Resultados de auditorias Desempeño de procesos
B35: Medición_Análisis_y_Mejora | C35: Resultados de auditoria Interna Resultados de Auditorías Externas | E35: Medición_Análisis_y_Mejora | F35: Conformidad del producto Estado de las acciones correctivas y mejoras
B36: Medición_Análisis_y_Mejora | C36: Información de los procesos y productos Retroalimentación con el cliente | E36: Medición_Análisis_y_Mejora | F36: Recomendación Para la mejora Necesidad de recurso
B37: Medición_Análisis_y_Mejora | C37: Mejoras al proceso Recurso proporcionado | E37: Medición_Análisis_y_Mejora | F37: Eficacia Información al cliente
B38: Medición_Análisis_y_Mejora | C38: Requisitos legales y reglamentarios Tendencia de los procesos | E38: Medición_Análisis_y_Mejora | F38: Toma de decisiones
B39: Medición_Análisis_y_Mejora | C39: Revisión por la Dirección Análisis FODA Matriz de Riesgos y Oportunidades | E39: Medición_Análisis_y_Mejora | F39: Conformidad del servicio Eficiencia
B40: Proyectos_e_Infraestructura | C40: Montos de Inversión del Organismo. Programa de Acciones de Recursos Federales. | E40: Proyectos_e_Infraestructura | F40: Liberación de Derechos de Conexión. Acta de entrega recepción.
B41: Proyectos_e_Infraestructura | C41: Solicitud de Factibilidad. Solicitud de Viabilidad comercial e industrial. Solicitud de Pre- factibilidad. | E41: Proyectos_e_Infraestructura | F41: Pago de estimaciones. Indicadores. Proyectos.
B42: Proyectos_e_Infraestructura | C42: Solicitud de Aprobación de Proyectos. Solicitud de Elaboración de Proyectos. | E42: Proyectos_e_Infraestructura | F42: Infraestructura. Información.
B43: Proyectos_e_Infraestructura | C43: Solicitud de Supervisión de Obras. Solicitud de Pruebas de Calidad. | E43: Proyectos_e_Infraestructura | F43: Viabilidad Comercial e Industrial. Prefactibilidades.
B44: Proyectos_e_Infraestructura | C44: Solicitud de Conexiones de Redes. Solicitud de Revisión de Estimaciones. | E44: Proyectos_e_Infraestructura | F44: Aprobación de Proyectos.
B45: Proyectos_e_Infraestructura | C45: Solicitud de Entrega-Recepción de Obras. Solicitud de Pagos de Derechos de Conexión. | E45: Proyectos_e_Infraestructura | F45: Factibilidades.
... B49: Comunicación | C49: Gestión de Riesgos. Acciones de seguimiento de las revisiones por la dirección previas. | E49: Comunicación | F49: Información Suficiente Y Oportuna para todos Los Colaboradores del Organismo.
B50: Comunicación | C50: Los cambios en las cuestiones externas e internas que sean pertinentes al sistema de gestión de calidad. | E50: Comunicación
B51: Comunicación | C51: Política de la Calidad Objetivos de la Calidad. Recursos proporcionados. Situaciones Externas. | E51: Comunicación
I59: Responsabilidad_de_la_Dirección | J59: DIAGRAMAS DE FLUJO
I60: Responsabilidad_de_la_Dirección
I61: Gestión_de_Recursos
I62: Mantenimiento_y_Calibración
...

Sheet ÁREAS QUE INTEGRAN PROCESOS
B2: Responsabilidad_de_la_Dirección | E2: REQUISITOS NORMA ISO 9001/2015
B3: ÁREAS QUE INTEGRAN EL PROCESO: | C3: Dirección: | D3: Procedimientos involucrados: | E3: participación DIRECTA (D) INDIRECTA (I) | F3: 4.1 | G3: 4.2 | H3: 4.3 | I3: 4.4 | J3: 5.1 | K3: 5.2 | L3: 5.3 | M3: 6.1 | N3: 6.2 | O3: 6.3 | P3: 7.1 | Q3: 7.2 | R3: 7.3 | S3: 7.4 | T3: 7.5 | U3: 8.1 | V3: 8.2 | W3: 8.3 | X3: 8.4 | Y3: 8.5 | Z3: 8.6 | AA3: 8.7 | AB3: 9.1 | AC3: 9.2 | AD3: 9.3 | AE3: 10.1 | AF3: 10.2 | AG3: 10.3 | AH3: CÓDIGO 1
B4: Alta Dirección | C4: General | F4: =IF($B4="","",_xlfn.XLOOKUP($B$2,PROCESOS,'MATRIZ REQUISITOS ISO'!D$7:D$14,"")) -> 1 | G4: =IF($B4="","",_xlfn.XLOOKUP($B$2,PROCESOS,'MATRIZ REQUISITOS ISO'!E$7:E$14,"")) -> 1 | H4: =IF($B4="","",_xlfn.XLOOKUP($B$2,PROCESOS,'MATRIZ REQUISITOS ISO'!F$7:F$14,"")) -> 1 | I4: =IF($B4="","",_xlfn.XLOOKUP($B$2,PROCESOS,'MATRIZ REQUISITOS ISO'!G$7:G$14,"")) -> 1 | J4: =IF($B4="","",_xlfn.XLOOKUP($B$2,PROCESOS,'MATRIZ REQUISITOS ISO'!H$7:H$14,"")) -> 1 | K4: =IF($B4="","",_xlfn.XLOOKUP($B$2,PROCESOS,'MATRIZ REQUISITOS ISO'!I$7:I$14,"")) -> 1 | L4: =IF($B4="","",_xlfn.XLOOKUP($B$2,PROCESOS,'MATRIZ REQUISITOS ISO'!J$7:J$14,"")) -> 1 | M4: =IF($B4="","",_xlfn.XLOOKUP($B$2,PROCESOS,'MATRIZ REQUISITOS ISO'!K$7:K$14,"")) -> 1 | ... AG4: =IF($B4="","",_xlfn.XLOOKUP($B$2,PROCESOS,'MATRIZ REQUISITOS ISO'!AE$7:AE$14,"")) -> 0 | AH4: =$B$2 -> Responsabilidad_de_la_Dirección
B5: Sistema de Gestión de Calidad | C5: General | D5: OOMPSC-01 OOMPSC-02 OOMPSC-03 OOMPSC-05 OOMPSC-09 OOMPSC-11 OOMPSC-14 OOMPSC-16 | F5: =IF($B5="","",_xlfn.XLOOKUP($B$2,PROCESOS,'MATRIZ REQUISITOS ISO'!D$7:D$14,"")) -> 1 | G5: =IF($B5="","",_xlfn.XLOOKUP($B$2,PROCESOS,'MATRIZ REQUISITOS ISO'!E$7:E$14,"")) -> 1 | H5: =IF($B5="","",_xlfn.XLOOKUP($B$2,PROCESOS,'MATRIZ REQUISITOS ISO'!F$7:F$14,"")) -> 1 | I5: =IF($B5="","",_xlfn.XLOOKUP($B$2,PROCESOS,'MATRIZ REQUISITOS ISO'!G$7:G$14,"")) -> 1 | J5: =IF($B5="","",_xlfn.XLOOKUP($B$2,PROCESOS,'MATRIZ REQUISITOS ISO'!H$7:H$14,"")) -> 1 | K5: =IF($B5="","",_xlfn.XLOOKUP($B$2,PROCESOS,'MATRIZ REQUISITOS ISO'!I$7:I$14,"")) -> 1 | L5: =IF($B5="","",_xlfn.XLOOKUP($B$2,PROCESOS,'MATRIZ REQUISITOS ISO'!J$7:J$14,"")) -> 1 | M5: =IF($B5="","",_xlfn.XLOOKUP($B$2,PROCESOS,'MATRIZ REQUISITOS ISO'!K$7:K$14,"")) -> 1 | ... AG5: =IF($B5="","",_xlfn.XLOOKUP($B$2,PROCESOS,'MATRIZ REQUISITOS ISO'!AE$7:AE$14,"")) -> 0 | AH5: =$B$2 -> Responsabilidad_de_la_Dirección
F6: =IF($B6="","",_xlfn.XLOOKUP($B$2,PROCESOS,'MATRIZ REQUISITOS ISO'!D$7:D$14,"")) | G6: =IF($B6="","",_xlfn.XLOOKUP($B$2,PROCESOS,'MATRIZ REQUISITOS ISO'!E$7:E$14,"")) | H6: =IF($B6="","",_xlfn.XLOOKUP($B$2,PROCESOS,'MATRIZ REQUISITOS ISO'!F$7:F$14,"")) | I6: =IF($B6="","",_xlfn.XLOOKUP($B$2,PROCESOS,'MATRIZ REQUISITOS ISO'!G$7:G$14,"")) | J6: =IF($B6="","",_xlfn.XLOOKUP($B$2,PROCESOS,'MATRIZ REQUISITOS ISO'!H$7:H$14,"")) | K6: =IF($B6="","",_xlfn.XLOOKUP($B$2,PROCESOS,'MATRIZ REQUISITOS ISO'!I$7:I$14,"")) | L6: =IF($B6="","",_xlfn.XLOOKUP($B$2,PROCESOS,'MATRIZ REQUISITOS ISO'!J$7:J$14,"")) | M6: =IF($B6="","",_xlfn.XLOOKUP($B$2,PROCESOS,'MATRIZ REQUISITOS ISO'!K$7:K$14,"")) | ... AG6: =IF($B6="","",_xlfn.XLOOKUP($B$2,PROCESOS,'MATRIZ REQUISITOS ISO'!AE$7:AE$14,"")) | AH6: =$B$2 -> Responsabilidad_de_la_Dirección
F7: =IF($B7="","",_xlfn.XLOOKUP($B$2,PROCESOS,'MATRIZ REQUISITOS ISO'!D$7:D$14,"")) | G7: =IF($B7="","",_xlfn.XLOOKUP($B$2,PROCESOS,'MATRIZ REQUISITOS ISO'!E$7:E$14,"")) | H7: =IF($B7="","",_xlfn.XLOOKUP($B$2,PROCESOS,'MATRIZ REQUISITOS ISO'!F$7:F$14,"")) | I7: =IF($B7="","",_xlfn.XLOOKUP($B$2,PROCESOS,'MATRIZ REQUISITOS ISO'!G$7:G$14,"")) | J7: =IF($B7="","",_xlfn.XLOOKUP($B$2,PROCESOS,'MATRIZ REQUISITOS ISO'!H$7:H$14,"")) | K7: =IF($B7="","",_xlfn.XLOOKUP($B$2,PROCESOS,'MATRIZ REQUISITOS ISO'!I$7:I$14,"")) | L7: =IF($B7="","",_xlfn.XLOOKUP($B$2,PROCESOS,'MATRIZ REQUISITOS ISO'!J$7:J$14,"")) | M7: =IF($B7="","",_xlfn.XLOOKUP($B$2,PROCESOS,'MATRIZ REQUISITOS ISO'!K$7:K$14,"")) | ... AG7: =IF($B7="","",_xlfn.XLOOKUP($B$2,PROCESOS,'MATRIZ REQUISITOS ISO'!AE$7:AE$14,"")) | AH7: =$B$2 -> Responsabilidad_de_la_Dirección
F8: =IF($B8="","",_xlfn.XLOOKUP($B$2,PROCESOS,'MATRIZ REQUISITOS ISO'!D$7:D$14,"")) | G8: =IF($B8="","",_xlfn.XLOOKUP($B$2,PROCESOS,'MATRIZ REQUISITOS ISO'!E$7:E$14,"")) | H8: =IF($B8="","",_xlfn.XLOOKUP($B$2,PROCESOS,'MATRIZ REQUISITOS ISO'!F$7:F$14,"")) | I8: =IF($B8="","",_xlfn.XLOOKUP($B$2,PROCESOS,'MATRIZ REQUISITOS ISO'!G$7:G$14,"")) | J8: =IF($B8="","",_xlfn.XLOOKUP($B$2,PROCESOS,'MATRIZ REQUISITOS ISO'!H$7:H$14,"")) | K8: =IF($B8="","",_xlfn.XLOOKUP($B$2,PROCESOS,'MATRIZ REQUISITOS ISO'!I$7:I$14,"")) | L8: =IF($B8="","",_xlfn.XLOOKUP($B$2,PROCESOS,'MATRIZ REQUISITOS ISO'!J$7:J$14,"")) | M8: =IF($B8="","",_xlfn.XLOOKUP($B$2,PROCESOS,'MATRIZ REQUISITOS ISO'!K$7:K$14,"")) | ... AG8: =IF($B8="","",_xlfn.XLOOKUP($B$2,PROCESOS,'MATRIZ REQUISITOS ISO'!AE$7:AE$14,"")) | AH8: =$B$2 -> Responsabilidad_de_la_Dirección
B9: Gestión_de_Recursos | E9: REQUISITOS NORMA ISO 9001/2015
B10: ÁREAS QUE INTEGRAN EL PROCESO: | C10: Dirección: | D10: Procedimientos involucrados: | E10: participación DIRECTA (D) INDIRECTA (I) | F10: 4.1 | G10: 4.2 | H10: 4.3 | I10: 4.4 | J10: 5.1 | K10: 5.2 | L10: 5.3 | M10: 6.1 | N10: 6.2 | O10: 6.3 | P10: 7.1 | Q10: 7.2 | R10: 7.3 | S10: 7.4 | T10: 7.5 | U10: 8.1 | V10: 8.2 | W10: 8.3 | X10: 8.4 | Y10: 8.5 | Z10: 8.6 | AA10: 8.7 | AB10: 9.1 | AC10: 9.2 | AD10: 9.3 | AE10: 10.1 | AF10: 10.2 | AG10: 10.3 | AH10: CÓDIGO 1
B11: Alcantarillado y Saneamiento | C11: Administrativa | D11: OOMPGS-02 OOMPGS-08 OOMPGS-10 | F11: =IF($B11="","",_xlfn.XLOOKUP($B$9,PROCESOS,'MATRIZ REQUISITOS ISO'!D$7:D$14,"")) -> 0 | G11: =IF($B11="","",_xlfn.XLOOKUP($B$9,PROCESOS,'MATRIZ REQUISITOS ISO'!E$7:E$14,"")) -> 0 | H11: =IF($B11="","",_xlfn.XLOOKUP($B$9,PROCESOS,'MATRIZ REQUISITOS ISO'!F$7:F$14,"")) -> 0 | I11: =IF($B11="","",_xlfn.XLOOKUP($B$9,PROCESOS,'MATRIZ REQUISITOS ISO'!G$7:G$14,"")) -> 2 | J11: =IF($B11="","",_xlfn.XLOOKUP($B$9,PROCESOS,'MATRIZ REQUISITOS ISO'!H$7:H$14,"")) -> 0 | K11: =IF($B11="","",_xlfn.XLOOKUP($B$9,PROCESOS,'MATRIZ REQUISITOS ISO'!I$7:I$14,"")) -> 0 | L11: =IF($B11="","",_xlfn.XLOOKUP($B$9,PROCESOS,'MATRIZ REQUISITOS ISO'!J$7:J$14,"")) -> 0 | M11: =IF($B11="","",_xlfn.XLOOKUP($B$9,PROCESOS,'MATRIZ REQUISITOS ISO'!K$7:K$14,"")) -> 2 | ... AG11: =IF($B11="","",_xlfn.XLOOKUP($B$9,PROCESOS,'MATRIZ REQUISITOS ISO'!AE$7:AE$14,"")) -> 2 | AH11: =$B$9 -> Gestión_de_Recursos
B12: Contabilidad | C12: Administrativa | D12: OOMPCO-01 OOMPCO-02 OOMPCO-03 OOMPCO-04 OOMPCO-05 OOMPCO-06 OOMPCO-09 | F12: =IF($B12="","",_xlfn.XLOOKUP($B$9,PROCESOS,'MATRIZ REQUISITOS ISO'!D$7:D$14,"")) -> 0 | G12: =IF($B12="","",_xlfn.XLOOKUP($B$9,PROCESOS,'MATRIZ REQUISITOS ISO'!E$7:E$14,"")) -> 0 | H12: =IF($B12="","",_xlfn.XLOOKUP($B$9,PROCESOS,'MATRIZ REQUISITOS ISO'!F$7:F$14,"")) -> 0 | I12: =IF($B12="","",_xlfn.XLOOKUP($B$9,PROCESOS,'MATRIZ REQUISITOS ISO'!G$7:G$14,"")) -> 2 | J12: =IF($B12="","",_xlfn.XLOOKUP($B$9,PROCESOS,'MATRIZ REQUISITOS ISO'!H$7:H$14,"")) -> 0 | K12: =IF($B12="","",_xlfn.XLOOKUP($B$9,PROCESOS,'MATRIZ REQUISITOS ISO'!I$7:I$14,"")) -> 0 | L12: =IF($B12="","",_xlfn.XLOOKUP($B$9,PROCESOS,'MATRIZ REQUISITOS ISO'!J$7:J$14,"")) -> 0 | M12: =IF($B12="","",_xlfn.XLOOKUP($B$9,PROCESOS,'MATRIZ REQUISITOS ISO'!K$7:K$14,"")) -> 2 | ... AG12: =IF($B12="","",_xlfn.XLOOKUP($B$9,PROCESOS,'MATRIZ REQUISITOS ISO'!AE$7:AE$14,"")) -> 2 | AH12: =$B$9 -> Gestión_de_Recursos
B13: Licitaciones | C13: Administrativa | D13: OOMPCL-01 OOMPCL-02 | F13: =IF($B13="","",_xlfn.XLOOKUP($B$9,PROCESOS,'MATRIZ REQUISITOS ISO'!D$7:D$14,"")) -> 0 | G13: =IF($B13="","",_xlfn.XLOOKUP($B$9,PROCESOS,'MATRIZ REQUISITOS ISO'!E$7:E$14,"")) -> 0 | H13: =IF($B13="","",_xlfn.XLOOKUP($B$9,PROCESOS,'MATRIZ REQUISITOS ISO'!F$7:F$14,"")) -> 0 | I13: =IF($B13="","",_xlfn.XLOOKUP($B$9,PROCESOS,'MATRIZ REQUISITOS ISO'!G$7:G$14,"")) -> 2 | J13: =IF($B13="","",_xlfn.XLOOKUP($B$9,PROCESOS,'MATRIZ REQUISITOS ISO'!H$7:H$14,"")) -> 0 | K13: =IF($B13="","",_xlfn.XLOOKUP($B$9,PROCESOS,'MATRIZ REQUISITOS ISO'!I$7:I$14,"")) -> 0 | L13: =IF($B13="","",_xlfn.XLOOKUP($B$9,PROCESOS,'MATRIZ REQUISITOS ISO'!J$7:J$14,"")) -> 0 | M13: =IF($B13="","",_xlfn.XLOOKUP($B$9,PROCESOS,'MATRIZ REQUISITOS ISO'!K$7:K$14,"")) -> 2 | ... AG13: =IF($B13="","",_xlfn.XLOOKUP($B$9,PROCESOS,'MATRIZ REQUISITOS ISO'!AE$7:AE$14,"")) -> 2 | AH13: =$B$9 -> Gestión_de_Recursos
B14: Recursos Humanos | C14: Administrativa | D14: OOMPRH-01 OOMPRH-04 OOMPRH-08 OOMPRH-09 OOMPRH-10 OOMPRH-11 OOMPRH-12 OOMPRH-16 | F14: =IF($B14="","",_xlfn.XLOOKUP($B$9,PROCESOS,'MATRIZ REQUISITOS ISO'!D$7:D$14,"")) -> 0 | G14: =IF($B14="","",_xlfn.XLOOKUP($B$9,PROCESOS,'MATRIZ REQUISITOS ISO'!E$7:E$14,"")) -> 0 | H14: =IF($B14="","",_xlfn.XLOOKUP($B$9,PROCESOS,'MATRIZ REQUISITOS ISO'!F$7:F$14,"")) -> 0 | I14: =IF($B14="","",_xlfn.XLOOKUP($B$9,PROCESOS,'MATRIZ REQUISITOS ISO'!G$7:G$14,"")) -> 2 | J14: =IF($B14="","",_xlfn.XLOOKUP($B$9,PROCESOS,'MATRIZ REQUISITOS ISO'!H$7:H$14,"")) -> 0 | K14: =IF($B14="","",_xlfn.XLOOKUP($B$9,PROCESOS,'MATRIZ REQUISITOS ISO'!I$7:I$14,"")) -> 0 | L14: =IF($B14="","",_xlfn.XLOOKUP($B$9,PROCESOS,'MATRIZ REQUISITOS ISO'!J$7:J$14,"")) -> 0 | M14: =IF($B14="","",_xlfn.XLOOKUP($B$9,PROCESOS,'MATRIZ REQUISITOS ISO'!K$7:K$14,"")) -> 2 | ... AG14: =IF($B14="","",_xlfn.XLOOKUP($B$9,PROCESOS,'MATRIZ REQUISITOS ISO'!AE$7:AE$14,"")) -> 2 | AH14: =$B$9 -> Gestión_de_Recursos
B15: Recursos Materiales | C15: Administrativa | D15: OOMPRM-01 OOMPRM-03 OOMPRM-07 OOMPRM-08 OOMIRM-01 | F15: =IF($B15="","",_xlfn.XLOOKUP($B$9,PROCESOS,'MATRIZ REQUISITOS ISO'!D$7:D$14,"")) -> 0 | G15: =IF($B15="","",_xlfn.XLOOKUP($B$9,PROCESOS,'MATRIZ REQUISITOS ISO'!E$7:E$14,"")) -> 0 | H15: =IF($B15="","",_xlfn.XLOOKUP($B$9,PROCESOS,'MATRIZ REQUISITOS ISO'!F$7:F$14,"")) -> 0 | I15: =IF($B15="","",_xlfn.XLOOKUP($B$9,PROCESOS,'MATRIZ REQUISITOS ISO'!G$7:G$14,"")) -> 2 | J15: =IF($B15="","",_xlfn.XLOOKUP($B$9,PROCESOS,'MATRIZ REQUISITOS ISO'!H$7:H$14,"")) -> 0 | K15: =IF($B15="","",_xlfn.XLOOKUP($B$9,PROCESOS,'MATRIZ REQUISITOS ISO'!I$7:I$14,"")) -> 0 | L15: =IF($B15="","",_xlfn.XLOOKUP($B$9,PROCESOS,'MATRIZ REQUISITOS ISO'!J$7:J$14,"")) -> 0 | M15: =IF($B15="","",_xlfn.XLOOKUP($B$9,PROCESOS,'MATRIZ REQUISITOS ISO'!K$7:K$14,"")) -> 2 | ... AG15: =IF($B15="","",_xlfn.XLOOKUP($B$9,PROCESOS,'MATRIZ REQUISITOS ISO'!AE$7:AE$14,"")) -> 2 | AH15: =$B$9 -> Gestión_de_Recursos
B16: Seguridad Industrial | C16: Administrativa | D16: OOMPIS-01 OOMPIS-02 OOMPIS-03 OOMPIS-05 | F16: =IF($B16="","",_xlfn.XLOOKUP($B$9,PROCESOS,'MATRIZ REQUISITOS ISO'!D$7:D$14,"")) -> 0 | G16: =IF($B16="","",_xlfn.XLOOKUP($B$9,PROCESOS,'MATRIZ REQUISITOS ISO'!E$7:E$14,"")) -> 0 | H16: =IF($B16="","",_xlfn.XLOOKUP($B$9,PROCESOS,'MATRIZ REQUISITOS ISO'!F$7:F$14,"")) -> 0 | I16: =IF($B16="","",_xlfn.XLOOKUP($B$9,PROCESOS,'MATRIZ REQUISITOS ISO'!G$7:G$14,"")) -> 2 | J16: =IF($B16="","",_xlfn.XLOOKUP($B$9,PROCESOS,'MATRIZ REQUISITOS ISO'!H$7:H$14,"")) -> 0 | K16: =IF($B16="","",_xlfn.XLOOKUP($B$9,PROCESOS,'MATRIZ REQUISITOS ISO'!I$7:I$14,"")) -> 0 | L16: =IF($B16="","",_xlfn.XLOOKUP($B$9,PROCESOS,'MATRIZ REQUISITOS ISO'!J$7:J$14,"")) -> 0 | M16: =IF($B16="","",_xlfn.XLOOKUP($B$9,PROCESOS,'MATRIZ REQUISITOS ISO'!K$7:K$14,"")) -> 2 | ... AG16: =IF($B16="","",_xlfn.XLOOKUP($B$9,PROCESOS,'MATRIZ REQUISITOS ISO'!AE$7:AE$14,"")) -> 2 | AH16: =$B$9 -> Gestión_de_Recursos
B17: Trámites Técnicos | C17: Técnica | D17: OOMPTT-05 OOMPTT-07 OOMPTT-08 | F17: =IF($B17="","",_xlfn.XLOOKUP($B$9,PROCESOS,'MATRIZ REQUISITOS ISO'!D$7:D$14,"")) -> 0 | G17: =IF($B17="","",_xlfn.XLOOKUP($B$9,PROCESOS,'MATRIZ REQUISITOS ISO'!E$7:E$14,"")) -> 0 | H17: =IF($B17="","",_xlfn.XLOOKUP($B$9,PROCESOS,'MATRIZ REQUISITOS ISO'!F$7:F$14,"")) -> 0 | I17: =IF($B17="","",_xlfn.XLOOKUP($B$9,PROCESOS,'MATRIZ REQUISITOS ISO'!G$7:G$14,"")) -> 2 | J17: =IF($B17="","",_xlfn.XLOOKUP($B$9,PROCESOS,'MATRIZ REQUISITOS ISO'!H$7:H$14,"")) -> 0 | K17: =IF($B17="","",_xlfn.XLOOKUP($B$9,PROCESOS,'MATRIZ REQUISITOS ISO'!I$7:I$14,"")) -> 0 | L17: =IF($B17="","",_xlfn.XLOOKUP($B$9,PROCESOS,'MATRIZ REQUISITOS ISO'!J$7:J$14,"")) -> 0 | M17: =IF($B17="","",_xlfn.XLOOKUP($B$9,PROCESOS,'MATRIZ REQUISITOS ISO'!K$7:K$14,"")) -> 2 | ... AG17: =IF($B17="","",_xlfn.XLOOKUP($B$9,PROCESOS,'MATRIZ REQUISITOS ISO'!AE$7:AE$14,"")) -> 2 | AH17: =$B$9 -> Gestión_de_Recursos
F18: =IF($B18="","",_xlfn.XLOOKUP($B$9,PROCESOS,'MATRIZ REQUISITOS ISO'!D$7:D$14,"")) | G18: =IF($B18="","",_xlfn.XLOOKUP($B$9,PROCESOS,'MATRIZ REQUISITOS ISO'!E$7:E$14,"")) | H18: =IF($B18="","",_xlfn.XLOOKUP($B$9,PROCESOS,'MATRIZ REQUISITOS ISO'!F$7:F$14,"")) | I18: =IF($B18="","",_xlfn.XLOOKUP($B$9,PROCESOS,'MATRIZ REQUISITOS ISO'!G$7:G$14,"")) | J18: =IF($B18="","",_xlfn.XLOOKUP($B$9,PROCESOS,'MATRIZ REQUISITOS ISO'!H$7:H$14,"")) | K18: =IF($B18="","",_xlfn.XLOOKUP($B$9,PROCESOS,'MATRIZ REQUISITOS ISO'!I$7:I$14,"")) | L18: =IF($B18="","",_xlfn.XLOOKUP($B$9,PROCESOS,'MATRIZ REQUISITOS ISO'!J$7:J$14,"")) | M18: =IF($B18="","",_xlfn.XLOOKUP($B$9,PROCESOS,'MATRIZ REQUISITOS ISO'!K$7:K$14,"")) | ... AG18: =IF($B18="","",_xlfn.XLOOKUP($B$9,PROCESOS,'MATRIZ REQUISITOS ISO'!AE$7:AE$14,"")) | AH18: =$B$9 -> Gestión_de_Recursos
B19: Mantenimiento_y_Calibración | E19: REQUISITOS NORMA ISO 9001/2015
B20: ÁREAS QUE INTEGRAN EL PROCESO: | C20: Dirección: | D20: Procedimientos involucrados: | E20: participación DIRECTA (D) INDIRECTA (I) | F20: 4.1 | G20: 4.2 | H20: 4.3 | I20: 4.4 | J20: 5.1 | K20: 5.2 | L20: 5.3 | M20: 6.1 | N20: 6.2 | O20: 6.3 | P20: 7.1 | Q20: 7.2 | R20: 7.3 | S20: 7.4 | T20: 7.5 | U20: 8.1 | V20: 8.2 | W20: 8.3 | X20: 8.4 | Y20: 8.5 | Z20: 8.6 | AA20: 8.7 | AB20: 9.1 | AC20: 9.2 | AD20: 9.3 | AE20: 10.1 | AF20: 10.2 | AG20: 10.3 | AH20: CÓDIGO 1
B21: Alcantarillado y Saneamiento | C21: Técnica | D21: OOMPGS-01 OOMPGS-02 OOMPGS-04 OOMPGS-06 OOMPGS-09 OOMPGS-10 OOMPGS-11 | F21: =IF($B21="","",_xlfn.XLOOKUP($B$19,PROCESOS,'MATRIZ REQUISITOS ISO'!D$7:D$14,"")) -> 0 | G21: =IF($B21="","",_xlfn.XLOOKUP($B$19,PROCESOS,'MATRIZ REQUISITOS ISO'!E$7:E$14,"")) -> 0 | H21: =IF($B21="","",_xlfn.XLOOKUP($B$19,PROCESOS,'MATRIZ REQUISITOS ISO'!F$7:F$14,"")) -> 0 | I21: =IF($B21="","",_xlfn.XLOOKUP($B$19,PROCESOS,'MATRIZ REQUISITOS ISO'!G$7:G$14,"")) -> 3 | J21: =IF($B21="","",_xlfn.XLOOKUP($B$19,PROCESOS,'MATRIZ REQUISITOS ISO'!H$7:H$14,"")) -> 0 | K21: =IF($B21="","",_xlfn.XLOOKUP($B$19,PROCESOS,'MATRIZ REQUISITOS ISO'!I$7:I$14,"")) -> 0 | L21: =IF($B21="","",_xlfn.XLOOKUP($B$19,PROCESOS,'MATRIZ REQUISITOS ISO'!J$7:J$14,"")) -> 0 | M21: =IF($B21="","",_xlfn.XLOOKUP($B$19,PROCESOS,'MATRIZ REQUISITOS ISO'!K$7:K$14,"")) -> 3 | ... AG21: =IF($B21="","",_xlfn.XLOOKUP($B$19,PROCESOS,'MATRIZ REQUISITOS ISO'!AE$7:AE$14,"")) -> 3 | AH21: =$B$19 -> Mantenimiento_y_Calibración
B22: Control de Calidad | C22: Técnica | D22: OOMPCC-27 OOMPCC-28 OOMPCC-29 OOMPCC-30 OOMPCC-31 OOMPCC-32 OOMPCC-33 OOMPCC-34 OOMPCC-43 OOMPCC-44 OOMPCC-48 OOMPCC-50 OOMPCC-51 OOMPCC-52 OOMPCC-58 OOMPCC-60 OOMPCC-61 OOMPCC-78 OOMPCC-79 | F22: =IF($B22="","",_xlfn.XLOOKUP($B$19,PROCESOS,'MATRIZ REQUISITOS ISO'!D$7:D$14,"")) -> 0 | G22: =IF($B22="","",_xlfn.XLOOKUP($B$19,PROCESOS,'MATRIZ REQUISITOS ISO'!E$7:E$14,"")) -> 0 | H22: =IF($B22="","",_xlfn.XLOOKUP($B$19,PROCESOS,'MATRIZ REQUISITOS ISO'!F$7:F$14,"")) -> 0 | I22: =IF($B22="","",_xlfn.XLOOKUP($B$19,PROCESOS,'MATRIZ REQUISITOS ISO'!G$7:G$14,"")) -> 3 | J22: =IF($B22="","",_xlfn.XLOOKUP($B$19,PROCESOS,'MATRIZ REQUISITOS ISO'!H$7:H$14,"")) -> 0 | K22: =IF($B22="","",_xlfn.XLOOKUP($B$19,PROCESOS,'MATRIZ REQUISITOS ISO'!I$7:I$14,"")) -> 0 | L22: =IF($B22="","",_xlfn.XLOOKUP($B$19,PROCESOS,'MATRIZ REQUISITOS ISO'!J$7:J$14,"")) -> 0 | M22: =IF($B22="","",_xlfn.XLOOKUP($B$19,PROCESOS,'MATRIZ REQUISITOS ISO'!K$7:K$14,"")) -> 3 | ... AG22: =IF($B22="","",_xlfn.XLOOKUP($B$19,PROCESOS,'MATRIZ REQUISITOS ISO'!AE$7:AE$14,"")) -> 3 | AH22: =$B$19 -> Mantenimiento_y_Calibración
